Workbook

Sheet README
B2: M/I Homes (MHO) — Coverage Initiation Model
B3: Three-statement model, DCF and comparable companies analysis. Built 04-Sep-2026; market data refreshed 11-Sep-2026.
B5: HOW TO USE THIS WORKBOOK
B6: Colour convention | C6: Blue = hard-coded input. Black = formula. Green = link to another sheet. Yellow = model output. Only blue cells should ever be typed over.
B7: Order of sheets | C7: Assumptions → Historicals → Segment Build → IS → BS → CF → DCF → Comps → Sensitivity → Summary. Everything projected flows from Assumptions.
B8: Where to flex first | C8: Assumptions, the "Southern competition premium" row. That single input carries the thesis. The Sensitivity sheet flexes it against mortgage rates live.
B9: Checks | C9: Segment Build has two tie-out rows against filed revenue and deliveries; BS has an assets-less-liabilities-and-equity check. All must read zero for 2023–2025.
B10: Recalculate | C10: The workbook is written with live formulas but no cached values. Open in Excel and press Ctrl+Alt+F9 (Cmd+Opt+F9 on Mac) for a full rebuild.
B12: SOURCES — every historical figure traces to one of these
B13: FY2025 Form 10-K | C13: Filed 13-Feb-2026, accession 0000799292-26-000006. Segment revenue, land and housing cost, segment operating income and depreciation come from Note 12, "Business Segments".
B14: Q4/FY2025 earnings release | C14: Exhibit 99.1 to Form 8-K filed 28-Jan-2026. Deliveries, new contracts, backlog and average sales price by region.
B15: Q4/FY2024 earnings release | C15: Exhibit 99.1 to Form 8-K filed 29-Jan-2025 (exhibit9914thqtr2024earnin.htm). 2024 and 2023 regional deliveries and contracts.
B16: Q4/FY2023 earnings release | C16: Exhibit 99.1 to Form 8-K filed 31-Jan-2024 (exhibit9914thqtr2023earnin.htm).
B17: Q2 2026 earnings release | C17: Exhibit 99.1 to Form 8-K filed 29-Jul-2026. Used to calibrate the 2026 estimate: 1H revenue $1,984.0m, EPS $5.57, 22.1% reported gross margin, 4,120 deliveries, $459k ASP.
B18: SEC XBRL | C18: data.sec.gov companyfacts, CIK 0000799292, for consolidated income statement, balance sheet and cash flow. Peer equity and net income from the same API.
B19: Rates | C19: FRED, pulled 11-Sep-2026. 30-yr fixed mortgage (MORTGAGE30US) 6.76% at 2026-09-10, up from a 5.98% trough this year; 2026 year-to-date average 6.38%. 10-yr UST (DGS10) 4.95%, 30-yr 5.37%. Annual mortgage figures are calendar-year averages of the weekly series, recomputed rather than typed — they had been lagged a year.
B20: Housing macro | C20: FRED, pulled 11-Sep-2026. Raleigh house price index (ATNHPIUS39580Q) +1.1% and Charlotte (ATNHPIUS16740Q) +1.5% over the year to Q2 2026, against 3.8% CPI — -2.6% and -2.3% in real terms. The FHFA All-Transactions index is NOT seasonally adjusted, so changes are measured year-over-year; a three-quarter window understates growth by about a point. NC private building permits (NCBPPRIVSA) declining through 2026.
B21: Prices | C21: stockanalysis.com, 04-Sep-2026 11:44 ET, for MHO and the six comparables.
B23: PROVENANCE — which numbers are facts and which are ours
B24: No company guidance exists | C24: M/I Homes issues no quantitative forward guidance. Neither the FY2025 nor the Q2 2026 release contains a delivery, revenue, margin or EPS target — only safe-harbour boilerplate. Every projected figure in this workbook is the analyst's, not the company's.
B25: Tier 1 — reported fact | C25: All of the Historicals sheet, plus the 1H26 figures used to calibrate 2026. Verified: 42 of 42 consolidated line items match SEC XBRL to the dollar; 24 of 24 segment figures match the 10-K segment note.
B26: Tier 2 — extrapolated from actuals | C26: Cost per home, selling and G&A percentages, corporate expense, tax rate, financial services margin, inventory turns. Each starts from a reported 2025 value and moves on a stated growth rate. Defensible without a view on the world.
B27: Tier 3 — pure judgement, no external anchor | C27: The mortgage rate path, the Southern and Northern competition premiums, delivery growth from 2027, gross ASP growth, and the buyback pace. These are forecasts with nothing behind them but reasoning. The competition premium is the most consequential and the least verifiable.
B28: How much rests on Tier 3 | C28: Of the $1.17 of 2027E EPS growth over 2026E: $0.90 is volume, price, cost and buyback; $-0.36 is the mortgage-rate decline; $0.64 — 55% — is the Southern competition premium decaying. The rate path and the premium together, 24% of the step-up, are Tier 3.
B29: Versus consensus | C29: Coverage is thin and stale. 7 analysts have rated MHO in the past twelve months (4 positive, 2 hold, 1 sell; most recent action: Zacks Research downgrade on 9 September 2026), consensus target $164.25 against mine of $160. But only ONE price target has been issued in the past three months, and the EPS estimates below are stamped 2026-06-24: 2026E $12.19 (range $11.43-$13.25), 2027E $14.08 (no range published). Mine are $11.98 and $13.15 — below on both years, but 2026 sits INSIDE the published range, not under it. Sources: marketbeat.com for ratings and target, stockanalysis.com for EPS; see data/consensus.json.
B31: MODELLING CONVENTIONS AND JUDGEMENT CALLS
B32: Revenue is built by region | C32: Deliveries x average selling price for Northern and Southern separately, never a blended growth rate. The thesis is entirely about regional mix, so a blended rate would assume away the question.
B33: Gross margin is a residual | C33: It is not an input. Incentive load reduces the realised price; cost per home is driven separately; the margin is what is left. That is what actually happens at a closing table.
B34: Incentive load has two terms | C34: A rate term (base + slope x the excess of the mortgage rate over a 5.5% neutral) and a competition premium. The second term is necessary: mortgage rates were flat between 2024 and 2025 while the Southern margin fell 680bp, so rates cannot be the explanation.
B35: Gross margin is shown two ways | C35: MHO reports gross margin on total revenue, which includes financial services revenue carrying no land or housing cost. That flatters the headline by roughly 200bp. The homebuilding-only margin is shown alongside it throughout.
B36: Charges are separated | C36: The $47.7m of 2025 inventory write-offs ($41.0m of it Southern) is stripped out of cost per home and modelled as its own line, so the underlying unit economics are visible.
B37: Financial services debt is excluded from net debt | C37: Warehouse facilities fund mortgage loans held for sale and are matched by those assets. Including them would overstate leverage.
B38: Stock compensation is a real cost | C38: Deducted in the free cash flow build. Adding it back would raise the DCF by roughly $6 per share.
B39: Other liabilities is the revenue-driven line | C39: Accounts payable, accrued compensation, customer deposits and warranty reserve are modelled at 14.4–14.6% of revenue, in line with 2025. The balance sheet ties without a plug.
B41: KNOWN LIMITATIONS — worth saying out loud
B42: Two segments, not seventeen | C42: MHO reports Northern and Southern only. Raleigh and Charlotte cannot be isolated from Florida and Texas in the filings, so "Southern" is the closest proxy for the North Carolina thesis available from public data. Division-level colour would have to come from management.
B43: Financial services is valued inside the consolidated DCF | C43: It is a mortgage origination business with a different risk profile and arguably deserves separate treatment. At 13% of segment operating income the simplification is tolerable, not correct.
B44: Terminal value carries most of the DCF | C44: Roughly 78%. That is unavoidable for a cyclical with heavy near-term working capital investment. The DCF still carries 60% of the target, because the alternative — the peer multiple — prices a re-rating the company has not earned.
B45: Peer book values are not all the same date | C45: Horton, Lennar and Toll have non-December year ends; each is taken from its most recent 10-Q. The staleness is at most one quarter.
B46: The comp set excludes NVR | C46: Its land-option model produces a structurally different balance sheet and a book multiple that is not comparable.

Sheet Summary
B2: M/I Homes (NYSE: MHO) — Initiation of Coverage
B3: Prepared 04-Sep-2026; market data refreshed 11-Sep-2026. All figures traceable to SEC filings; see README for sources.
B5: RECOMMENDATION
B6: Rating | C6: NEUTRAL
B7: 12-month price target ($) | C7: 160 | L7: Weighted across the four methods below. See the note for how the weights were chosen.
B8: Current price ($) | C8: =Assumptions!$C$62
B9: Implied total return (%) | C9: =C7/C8-1 | L9: No dividend. The entire return is price plus the buyback.
B10: Market capitalisation ($m) | C10: =Assumptions!$C$62*Assumptions!$C$63/1000
B12: THE CALL IN ONE PARAGRAPH
B13: North Carolina led the country in net domestic in-migration in the year to July 2025. M/I Homes' Southern segment — which contains
B14: Raleigh and Charlotte — nonetheless saw its operating margin fall from 18.1% to 10.4% in a single year, while the unfashionable Northern
B15: segment held at 14.7%. Mortgage rates were flat across that period, so this was not a rate shock: it was competition for a buyer who could
B16: not afford the house. Cost per home barely moved. The whole margin decline was price given back at the closing table.
B17: MHO is a well-run, net-cash builder buying back 5% of its shares a year, and at 1.10x book it is not expensive. But it now earns
B18: roughly its cost of equity. Return on equity has fallen to 9.3% on trailing numbers, and at a 12.0% cost of equity today's
B19: multiple already pays for a normalised return near 13%. My base case reaches only 9.8% by 2028, and only by assuming a
B20: competitive recovery I cannot verify. I initiate at Neutral: the margin recovery is priced but not yet earned.
B22: VALUATION SUMMARY — where the methods agree and where they do not
B23: Method | C23: Value $ | E23: vs price | G23: Weight | H23: Contribution
B24: Discounted cash flow (rolled forward 12 months) | C24: =DCF!$C$47*(1+DCF!$C$9/100) | E24: =C24/C8-1 | G24: 0.6 | H24: =C24*G24 | L24: What the business earns, and what is left for shareholders after land absorbs its share. Weighted more heavily because it is the only method that prices the return gap.
B25: Peer median P/B on Sep-2027E book | C25: =Comps!H34 | E25: =C25/C8-1 | G25: 0.4 | H25: =C25*G25 | L25: What the market pays other builders for a dollar of book. The multiple comes from the comp set, not from MHO, which is what makes this independent of the DCF and able to disagree with the current price.
B26: Weighted value per share | G26: =SUM(G24:G25) | H26: =SUM(H24:H25)
B27: Cross-check: probability-weighted value (25/50/25 across the scenarios below) | H27: =0.25*F31+0.5*F32+0.25*F33 | L27: Not a second price target — a test of the rating. A probability-weighted value below the share price is what makes this a Sell rather than a Hold.
B29: SCENARIOS
B30: Scenario | C30: 2027E EPS | D30: 2030E EPS | E30: 2028E ROE | F30: Value $ | G30: vs price | L30: What has to be true
B31: Bull | C31: 15.826862 | D31: 25.981132 | E31: 0.1210539 | F31: 199 | G31: =F31/$C$8-1 | L31: Mortgage rates to 5.4% by 2028 and Sunbelt spec supply clears: the Southern competition premium falls to 1.9pp of price by 2028. Priced on the multiple the market pays the peer earning that return.
B32: Base | C32: 13.148648 | D32: 19.236986 | E32: 0.098282261 | F32: 160 | G32: =F32/$C$8-1 | L32: Rates grind to ~6.1%; the Southern competition premium decays but never disappears. Southern operating margin recovers part-way, not to the 18% of 2024. Priced on the peer median multiple.
B33: Bear | C33: 9.1767728 | D33: 9.262717 | E33: 0.062183247 | F33: 100 | G33: =F33/$C$8-1 | L33: Rates hold near 7%; Sunbelt oversupply persists and the Southern premium ratchets to 5.6pp. Deliveries fall, cost inflation resumes. Priced on the multiple the market pays the peer earning that return.
B35: KEY FINANCIALS
B36: ($ in millions except per-share) | C36: 2024A | D36: 2025A | E36: 2026E | F36: 2027E | G36: 2028E
B37: Revenue | C37: =IS!D11/1000 | D37: =IS!E11/1000 | E37: =IS!F11/1000 | F37: =IS!G11/1000 | G37: =IS!H11/1000
B38: Homes delivered | C38: ='Segment Build'!D8+'Segment Build'!D18 | D38: ='Segment Build'!E8+'Segment Build'!E18 | E38: ='Segment Build'!F8+'Segment Build'!F18 | F38: ='Segment Build'!G8+'Segment Build'!G18 | G38: ='Segment Build'!H8+'Segment Build'!H18
B39: Gross margin — homebuilding (%) | C39: =1-IS!D14/(IS!D8+IS!D9) | D39: =1-IS!E14/(IS!E8+IS!E9) | E39: =1-IS!F14/(IS!F8+IS!F9) | F39: =1-IS!G14/(IS!G8+IS!G9) | G39: =1-IS!H14/(IS!H8+IS!H9)
B40: Operating margin (%) | C40: =IS!D26/IS!D11 | D40: =IS!E26/IS!E11 | E40: =IS!F26/IS!F11 | F40: =IS!G26/IS!G11 | G40: =IS!H26/IS!H11
B41: Southern operating margin (%) | C41: =IS!D42/IS!D9 | D41: =IS!E42/IS!E9 | E41: =IS!F42/IS!F9 | F41: =IS!G42/IS!G9 | G41: =IS!H42/IS!H9
B42: Northern operating margin (%) | C42: =IS!D41/IS!D8 | D42: =IS!E41/IS!E8 | E42: =IS!F41/IS!F8 | F42: =IS!G41/IS!G8 | G42: =IS!H41/IS!H8
B43: Diluted EPS ($) | C43: =IS!D37 | D43: =IS!E37 | E43: =IS!F37 | F43: =IS!G37 | G43: =IS!H37
B44: Book value per share ($) | C44: =BS!D25 | D44: =BS!E25 | E44: =BS!F25 | F44: =BS!G25 | G44: =BS!H25
B45: Return on equity (%) | C45: =BS!D29 | D45: =BS!E29 | E45: =BS!F29 | F45: =BS!G29 | G45: =BS!H29
B46: Net debt / (net cash) | C46: =BS!D27/1000 | D46: =BS!E27/1000 | E46: =BS!F27/1000 | F46: =BS!G27/1000 | G46: =BS!H27/1000

Sheet Assumptions
B2: Assumptions & Drivers
B3: Blue = hard-coded input. Every projected line in this model traces back to this sheet. Flex the incentive block first — it is where the thesis lives.
B5: DRIVER | C5: 2023A | D5: 2024A | E5: 2025A | F5: 2026E | G5: 2027E | H5: 2028E | I5: 2029E | J5: 2030E
B7: MACRO
B8: 30-yr fixed mortgage rate (annual avg, %) | C8: 6.807 | D8: 6.721 | E8: 6.595 | F8: 6.49 | G8: 6.76 | H8: 6.76 | I8: 6.76 | J8: 6.76 | L8: 2023-25 actual: calendar-year average of FRED MORTGAGE30US, pulled 11-Sep-2026. These were previously entered lagged one year. 2026E is 36 weeks observed plus the spot held to year end. 2027E+ HOLDS THE SPOT of 6.76% (2026-09-10): I do not forecast rates, so the target carries no rate view. The previous path declined to 5.90%, which implied the 10-yr Treasury falling to about 4.09% and was worth roughly $7/share.
B9: Neutral mortgage rate (%) | C9: 5.5 | L9: Rate at which a builder needs no abnormal incentive. Single input — applies to all years.
B10: Inflation (%) | C10: 2.5 | L10: THE SINGLE INFLATION INPUT. Every nominal dollar driver below is grown from its 2025 actual at this rate, and it is also the terminal growth rate, so one number governs both — flex it here and it propagates. Ratio drivers are NOT inflated: a ratio is inflation-neutral by construction, so they are held at their most recent observed level instead. Measured CPI over the year to Q2-2026 was 3.8%; using that instead of 2.50% moves the DCF by about $0.34 and would contradict the terminal growth rate, so it is not worth the inconsistency.
B11: Real growth in perpetuity (%) | C11: 0 | L11: Real growth ON TOP of inflation, in perpetuity. Terminal growth is not a separate input: it is derived as inflation + real growth = 2.50% + 0.00% = 2.50%, so the two cannot drift apart. Zero real growth is a deliberate, conservative choice — it says the company grows with prices but not faster, shrinking slowly against a growing economy. Each 50bp here is worth roughly $3.50 a share; see the WACC x terminal growth grid on the DCF sheet.
B13: INCENTIVE INTENSITY — incentive load (% of gross ASP) = base + rate slope x (mortgage rate − neutral) + competition premium
B14: Northern — base incentive (% of gross ASP) | C14: 1.015
B15: Northern — rate slope (pp per 100bp above neutral) | C15: 0.9
B16: Northern — competition premium (pp) | C16: 0 | D16: 0 | E16: 1.256 | F16: 3.51 | G16: 3.15 | H16: 2.9 | I16: 2.75 | J16: 2.65 | L16: Incentive over and above what the rate alone justifies. Zero in 2023-24 by construction. The 1.26pp for 2025 is NOT assumed: the 10-K discloses Northern per-home incentives rose $6.5k while mortgage rates FELL (6.80%->6.72%), so the rate term cannot account for it and the residual is forced positive. 2026E+ (3.51pp falling to 2.65pp) is forecast, not calibrated, and is the least defended input in the model - the note argues a competition story for the South, not the North. Holding it at the 2025 level instead raises 2027E EPS by about $1.07.
B17: Southern — base incentive (% of gross ASP) | C17: 2.05
B18: Southern — rate slope (pp per 100bp above neutral) | C18: 1.2
B19: Southern — competition premium (pp) | C19: 0 | D19: 0 | E19: 2.04 | F19: 4.371 | G19: 3.75 | H19: 3.3 | I19: 3 | J19: 2.8 | L19: THE KEY INPUT, and the three years are known with very different confidence. 2023-24: zero by construction, the base period. 2025 (2.04pp): CALIBRATED, not chosen - solved together with the base rate from four figures the 10-K discloses (total incentives of $131.3m in 2024 and $200.0m in 2025, and per-home increases of $6.5k Northern and $8.8k Southern). Mortgage rates FELL 12.6bp over that year, so a rate-only model predicts incentives easing when they in fact nearly doubled. 2026 (4.37pp): NOT calibrated - MHO discloses incentives annually, not quarterly, so there is nothing to solve against. It is set by hand so the full year lands near reported 1H26 margin and ASP. 2027-30: JUDGEMENT. A decay of about 11%/yr that never reaches zero, still carrying 2.80pp in 2030. Nothing observable supports the shape; it is the single least defended input in the model and the reason the sensitivity grid matters more than the point estimate. Flex this before anything else.
B21: VOLUME, PRICE AND COST (growth rates, % — projections only)
B22: Deliveries growth — Northern (%) | F22: -3.9 | G22: 3.5 | H22: 4 | I22: 3.25 | J22: 3 | L22: 2026E is set by hand so the full year lands near reported 1H 2026 (4,120 deliveries, $459k ASP, $5.57 EPS, 22.1% reported gross margin) — it is NOT solved from those figures, it is eyeballed against them. 2027E+ is judgement with no external anchor: see README, Tier 3. Full-year 2026E implies a 2H 7.6% above 1H, against an actual 6.3% step in 2025.
B23: Deliveries growth — Southern (%) | F23: -4.3 | G23: 5 | H23: 5.5 | I23: 4.25 | J23: 4 | L23: 2026E is set by hand so the full year lands near reported 1H 2026 (4,120 deliveries, $459k ASP, $5.57 EPS, 22.1% reported gross margin) — it is NOT solved from those figures, it is eyeballed against them. 2027E+ is judgement with no external anchor: see README, Tier 3.
B24: Gross ASP growth — Northern (%) | F24: 1 | G24: 2 | H24: 2.25 | I24: 2.5 | J24: 2.5 | L24: Gross ASP = list price before incentives. 2026E is set by hand so the full year lands near reported 1H 2026 (4,120 deliveries, $459k ASP, $5.57 EPS, 22.1% reported gross margin) — it is NOT solved from those figures, it is eyeballed against them. 2027E+ is judgement with no external anchor: see README, Tier 3.
B25: Gross ASP growth — Southern (%) | F25: -1.5 | G25: 1 | H25: 2 | I25: 2.25 | J25: 2.25 | L25: 2026E is set by hand so the full year lands near reported 1H 2026 (4,120 deliveries, $459k ASP, $5.57 EPS, 22.1% reported gross margin) — it is NOT solved from those figures, it is eyeballed against them. 2027E+ is judgement with no external anchor: see README, Tier 3.
B26: Cost per home growth — Northern (%) | F26: 0 | G26: 2.2 | H26: 2.4 | I26: 2.5 | J26: 2.5 | L26: 2026E is set by hand so the full year lands near reported 1H 2026 (4,120 deliveries, $459k ASP, $5.57 EPS, 22.1% reported gross margin) — it is NOT solved from those figures, it is eyeballed against them. 2027E+ is judgement with no external anchor: see README, Tier 3.
B27: Cost per home growth — Southern (%) | F27: -0.3 | G27: 2 | H27: 2.3 | I27: 2.5 | J27: 2.5 | L27: Land + stick-and-brick + closing cost per unit delivered. 2026E is set by hand so the full year lands near reported 1H 2026 (4,120 deliveries, $459k ASP, $5.57 EPS, 22.1% reported gross margin) — it is NOT solved from those figures, it is eyeballed against them. 2027E+ is judgement with no external anchor: see README, Tier 3.
B29: OTHER INCOME STATEMENT DRIVERS
B30: Land sale revenue ($000) | F30: 18085.1 | G30: 18537.2 | H30: 19000.7 | I30: 19475.7 | J30: 19962.6 | L30: Grown from its 2025 actual at the single inflation input above (the nominal rule) — not a hand-set path. 2025 actual $17.6m. Land sales are incidental to the thesis; this line is small and is not forecast independently.
B31: Financial services revenue growth (%) | F31: -4.1 | G31: 4.25 | H31: 4.75 | I31: 3.75 | J31: 3.5 | L31: DERIVED, not assumed: financial services originates mortgages for buyers of these homes, so its revenue tracks deliveries. This row is the average of the two delivery growth rates above and moves with them automatically.
B32: Selling expense (% of homebuilding revenue) | F32: 6.22 | G32: 6.22 | H32: 6.22 | I32: 6.22 | J32: 6.22 | L32: Held flat at the most recent observed level (the ratio rule): a ratio is inflation-neutral, so holding it IS the inflation adjustment. Held at 6.22%, the 1H 2026 actual ($119.4m on $1,920.4m of homebuilding revenue) rather than the 5.72% of FY2025 — using the older figure would override reported data.
B33: Homebuilding G&A (% of homebuilding revenue) | F33: 2.76 | G33: 2.76 | H33: 2.76 | I33: 2.76 | J33: 2.76 | L33: Held flat at the most recent observed level (the ratio rule): a ratio is inflation-neutral, so holding it IS the inflation adjustment. Held at 2.76%, the FY2025 actual. Total company G&A is running flat year-on-year in 1H26, which is consistent with this.
B34: Corporate / unallocated ($000) | F34: -91872.8 | G34: -94169.6 | H34: -96523.9 | I34: -98937 | J34: -101410.4 | L34: Grown from its 2025 actual at the single inflation input above (the nominal rule) — not a hand-set path. 2025 actual −$89.6m (total operating income less the three segments). Not charged to either region in the 10-K segment note.
B35: Inventory impairment & write-offs ($000) | F35: 16000 | G35: 9000 | H35: 7000 | I35: 7000 | J35: 7000 | L35: $47.7m in 2025, of which $41.0m Southern.
B36: Net interest income ($000) | F36: 18000 | G36: 18000 | H36: 18000 | I36: 18000 | J36: 18000 | L36: Held flat. Depends on the cash balance and short rates, neither of which this model forecasts; it is small enough that a path would be false precision.
B37: Land sale gross margin (%) | C37: 7 | L37: Land sales carried a 24% gross margin in 2025 and 29% in 2024, but on only $17.6m and $12.6m of revenue. 7% is deliberately conservative on a line too small to matter.
B38: Share of land revenue in Southern (%) | C38: 65 | L38: NOT DISCLOSED. The 10-K segment note gives total segment revenue only, so land sales cannot be split by region from the filings. This input does that split, and it matters because segment revenue includes land sales while average selling price must not. Moving it from 0% to 100% Southern changes the two-year Southern price decline by about $2k a home, so the thesis does not turn on it.
B39: Financial services pre-tax margin (%) | C39: 54.5 | L39: 54.3% in 2025 (op income $68.2m on revenue $125.5m).
B40: Effective tax rate (%) | C40: 23.5 | L40: 23.5% vs 23.5% in 2025; energy-efficiency credits keep it below statutory + state.
B42: BALANCE SHEET & CASH FLOW DRIVERS
B43: Inventory turns (homebuilding revenue / ending inventory) | F43: 1.27 | G43: 1.27 | H43: 1.27 | I43: 1.27 | J43: 1.27 | L43: 1.27x in 2025. Falls in 2026E as deliveries drop faster than the land pipeline.
B44: Other operating assets (% of revenue) | F44: 14.35 | G44: 14.35 | H44: 14.35 | I44: 14.35 | J44: 14.35 | L44: Held flat at the most recent observed level (the ratio rule): a ratio is inflation-neutral, so holding it IS the inflation adjustment. Held at 14.35%, the 2025 actual.
B45: Other liabilities (% of revenue) | F45: 14.44 | G45: 14.44 | H45: 14.44 | I45: 14.44 | J45: 14.44 | L45: A/P, accrued comp, customer deposits, warranty reserve. 14.4% in 2025.
B46: Capital expenditure ($000) | F46: 9849.2 | G46: 10095.5 | H46: 10347.8 | I46: 10606.5 | J46: 10871.7 | L46: Grown from its 2025 actual at the single inflation input above (the nominal rule) — not a hand-set path. 2025 actual $9.6m. Real investment for a builder is land, which sits in inventory, not here.
B47: Depreciation & amortisation ($000) | F47: 19370.4 | G47: 19854.7 | H47: 20351.1 | I47: 20859.9 | J47: 21381.4 | L47: Grown from its 2025 actual at the single inflation input above (the nominal rule) — not a hand-set path. 2025 actual $18.9m.
...

Sheet Historicals
B2: Historicals — as reported
B3: Hand-entered from the FY2025 10-K (filed 13-Feb-2026) and the Q4 earnings releases. Nothing on this sheet is calculated except the check rows. Source for each block in column L.
B5: ($ in thousands unless noted) | C5: 2023A | D5: 2024A | E5: 2025A | F5: 2026E | G5: 2027E | H5: 2028E | I5: 2029E | J5: 2030E
B7: OPERATING — by region [FY2025 10-K MD&A; Q4 earnings releases 2024–2026]
B8: Homes delivered — Northern | C8: 3169 | D8: 3873 | E8: 3716 | L8: FY25 rel. p.6 / FY24 rel. / FY23 rel.
B9: Homes delivered — Southern | C9: 4943 | D9: 5182 | E9: 5205
B10: Homes delivered — total | C10: =C8+C9 | D10: =D8+D9 | E10: =E8+E9 | L10: Ties to 8,112 / 9,055 / 8,921 as reported.
B11: New contracts — Northern | C11: 3361 | D11: 3761 | E11: 3416
B12: New contracts — Southern | C12: 4616 | D12: 4823 | E12: 4783
B13: Backlog units — year end | C13: 3002 | D13: 2531 | E13: 1809 | L13: 3,002 / 2,531 / 1,809 — down 40% over two years.
B14: Active communities | D14: 220 | E14: 232
B16: SEGMENT REVENUE [FY2025 10-K, Note 12 “Business Segments”]
B17: Northern homebuilding | C17: 1523943 | D17: 1900013 | E17: 1890457 | L17: FY2025 10-K, Note 12 Business Segments (R84) - filed 2026-02-13, acc 0000799292-26-000006
B18: Southern homebuilding | C18: 2415730 | D18: 2488451 | E18: 2401861
B19: Financial services | C19: 93829 | D19: 116206 | E19: 125463
B20: Total revenue | C20: =SUM(C17:C19) | D20: =SUM(D17:D19) | E20: =SUM(E17:E19) | L20: Ties to $4,033.5m / $4,504.7m / $4,417.8m as reported.
B21: of which: land sale revenue (company total) | C21: 25301 | D21: 12635 | E21: 17644 | L21: FY23/24/25 8-K Ex-99.1, "Land revenue". Segment revenue above INCLUDES this; it is not a home price. Not disclosed by segment, so it is split on the Assumptions land-split input.
B22: of which: land sale gross profit (company total) | C22: 3360 | D22: 3709 | E22: 4196
B24: SEGMENT LAND & HOUSING COST
B25: Northern | C25: 1228949 | D25: 1480326 | E25: 1475438
B26: Southern | C26: 1785624 | D26: 1825455 | E26: 1925144
B27: of which: inventory write-offs — Northern | C27: 0 | D27: 0 | E27: 6700 | L27: 2025 total valuation adjustments $47.7m.
B28: of which: inventory write-offs — Southern | C28: 0 | D28: 0 | E28: 41000
B30: SEGMENT OPERATING INCOME
B31: Northern homebuilding | C31: 176320 | D31: 281099 | E31: 278056
B32: Southern homebuilding | C32: 440168 | D32: 450598 | E32: 249969
B33: Financial services | C33: 48714 | D33: 63380 | E33: 68160
B34: Corporate / unallocated | C34: =Historicals!C35-C31-C32-C33 | D34: =Historicals!D35-D31-D32-D33 | E34: =Historicals!E35-E31-E32-E33
B35: Total operating income | C35: 587222 | D35: 706094 | E35: 506553
B37: SEGMENT SELLING AND G&A
B38: Selling — Northern | C38: 81847 | D38: 95680 | E38: 95860
B39: Selling — Southern | C39: 124860 | D39: 136198 | E39: 149457
B40: G&A — Northern | C40: 36827 | D40: 42908 | E40: 41103
B41: G&A — Southern | C41: 65078 | D41: 76200 | E41: 77291
B42: G&A — Financial services | C42: 45115 | D42: 52826 | E42: 57303
B44: CONSOLIDATED INCOME STATEMENT [FY2025 10-K; XBRL companyfacts CIK 0000799292]
B45: Land and housing costs | C45: 3014573 | D45: 3305781 | E45: 3400582
B46: Income before income taxes | C46: 607277 | D46: 733608 | E46: 526588
B47: Provision for income taxes | C47: 141912 | D47: 169883 | E47: 123647
B48: Net income | C48: 465365 | D48: 563725 | E48: 402941
...

Sheet Segment Build
B2: Segment Build — deliveries x ASP, and the incentive bridge to gross margin
B3: Revenue is built region by region, never off a blended growth rate. Gross margin falls out of the arithmetic: incentives cut the price, costs do not move, so the margin is the residual.
B5: ($ in thousands unless noted) | C5: 2023A | D5: 2024A | E5: 2025A | F5: 2026E | G5: 2027E | H5: 2028E | I5: 2029E | J5: 2030E
B7: NORTHERN HOMEBUILDING — Columbus, Cincinnati, Indianapolis, Chicago, Minneapolis, Detroit
B8: Homes delivered | C8: =Historicals!C8 | D8: =Historicals!D8 | E8: =Historicals!E8 | F8: =E8*(1+Assumptions!F22/100) | G8: =F8*(1+Assumptions!G22/100) | H8: =G8*(1+Assumptions!H22/100) | I8: =H8*(1+Assumptions!I22/100) | J8: =I8*(1+Assumptions!J22/100)
B9: Gross ASP — list price before incentives ($000) | C9: =C11/(1-C10/100) | D9: =D11/(1-D10/100) | E9: =E11/(1-E10/100) | F9: =E9*(1+Assumptions!F24/100) | G9: =F9*(1+Assumptions!G24/100) | H9: =G9*(1+Assumptions!H24/100) | I9: =H9*(1+Assumptions!I24/100) | J9: =I9*(1+Assumptions!J24/100)
B10: Incentive load (% of gross ASP) | C10: =Assumptions!$C$14+Assumptions!$C$15*MAX(0,Assumptions!C8-Assumptions!$C$9)+Assumptions!C16 | D10: =Assumptions!$C$14+Assumptions!$C$15*MAX(0,Assumptions!D8-Assumptions!$C$9)+Assumptions!D16 | E10: =Assumptions!$C$14+Assumptions!$C$15*MAX(0,Assumptions!E8-Assumptions!$C$9)+Assumptions!E16 | F10: =Assumptions!$C$14+Assumptions!$C$15*MAX(0,Assumptions!F8-Assumptions!$C$9)+Assumptions!F16 | G10: =Assumptions!$C$14+Assumptions!$C$15*MAX(0,Assumptions!G8-Assumptions!$C$9)+Assumptions!G16 | H10: =Assumptions!$C$14+Assumptions!$C$15*MAX(0,Assumptions!H8-Assumptions!$C$9)+Assumptions!H16 | I10: =Assumptions!$C$14+Assumptions!$C$15*MAX(0,Assumptions!I8-Assumptions!$C$9)+Assumptions!I16 | J10: =Assumptions!$C$14+Assumptions!$C$15*MAX(0,Assumptions!J8-Assumptions!$C$9)+Assumptions!J16 | L10: Rate-driven only through 2025.
B11: Net ASP — realised ($000) | C11: =(Historicals!C17-Historicals!C21*(1-Assumptions!$C$38/100))/C8 | D11: =(Historicals!D17-Historicals!D21*(1-Assumptions!$C$38/100))/D8 | E11: =(Historicals!E17-Historicals!E21*(1-Assumptions!$C$38/100))/E8 | F11: =F9*(1-F10/100) | G11: =G9*(1-G10/100) | H11: =H9*(1-H10/100) | I11: =I9*(1-I10/100) | J11: =J9*(1-J10/100)
B12: Cost per home, ex-charges ($000) | C12: =(Historicals!C25-Historicals!C27-(Historicals!C21-Historicals!C22)*(1-Assumptions!$C$38/100))/C8 | D12: =(Historicals!D25-Historicals!D27-(Historicals!D21-Historicals!D22)*(1-Assumptions!$C$38/100))/D8 | E12: =(Historicals!E25-Historicals!E27-(Historicals!E21-Historicals!E22)*(1-Assumptions!$C$38/100))/E8 | F12: =E12*(1+Assumptions!F26/100) | G12: =F12*(1+Assumptions!G26/100) | H12: =G12*(1+Assumptions!H26/100) | I12: =H12*(1+Assumptions!I26/100) | J12: =I12*(1+Assumptions!J26/100)
B13: Gross profit per home ($000) | C13: =C11-C12 | D13: =D11-D12 | E13: =E11-E12 | F13: =F11-F12 | G13: =G11-G12 | H13: =H11-H12 | I13: =I11-I12 | J13: =J11-J12
B14: Gross margin, ex-charges (%) | C14: =1-C12/C11 | D14: =1-D12/D11 | E14: =1-E12/E11 | F14: =1-F12/F11 | G14: =1-G12/G11 | H14: =1-H12/H11 | I14: =1-I12/I11 | J14: =1-J12/J11
B15: Housing revenue | C15: =C8*C11 | D15: =D8*D11 | E15: =E8*E11 | F15: =F8*F11 | G15: =G8*G11 | H15: =H8*H11 | I15: =I8*I11 | J15: =J8*J11
B17: SOUTHERN HOMEBUILDING — Tampa, Orlando, Sarasota, Fort Myers, CHARLOTTE, RALEIGH, Houston, San Antonio, Austin, Dallas, Nashville
B18: Homes delivered | C18: =Historicals!C9 | D18: =Historicals!D9 | E18: =Historicals!E9 | F18: =E18*(1+Assumptions!F23/100) | G18: =F18*(1+Assumptions!G23/100) | H18: =G18*(1+Assumptions!H23/100) | I18: =H18*(1+Assumptions!I23/100) | J18: =I18*(1+Assumptions!J23/100)
B19: Gross ASP — list price before incentives ($000) | C19: =C21/(1-C20/100) | D19: =D21/(1-D20/100) | E19: =E21/(1-E20/100) | F19: =E19*(1+Assumptions!F25/100) | G19: =F19*(1+Assumptions!G25/100) | H19: =G19*(1+Assumptions!H25/100) | I19: =H19*(1+Assumptions!I25/100) | J19: =I19*(1+Assumptions!J25/100)
B20: Incentive load (% of gross ASP) | C20: =Assumptions!$C$17+Assumptions!$C$18*MAX(0,Assumptions!C8-Assumptions!$C$9)+Assumptions!C19 | D20: =Assumptions!$C$17+Assumptions!$C$18*MAX(0,Assumptions!D8-Assumptions!$C$9)+Assumptions!D19 | E20: =Assumptions!$C$17+Assumptions!$C$18*MAX(0,Assumptions!E8-Assumptions!$C$9)+Assumptions!E19 | F20: =Assumptions!$C$17+Assumptions!$C$18*MAX(0,Assumptions!F8-Assumptions!$C$9)+Assumptions!F19 | G20: =Assumptions!$C$17+Assumptions!$C$18*MAX(0,Assumptions!G8-Assumptions!$C$9)+Assumptions!G19 | H20: =Assumptions!$C$17+Assumptions!$C$18*MAX(0,Assumptions!H8-Assumptions!$C$9)+Assumptions!H19 | I20: =Assumptions!$C$17+Assumptions!$C$18*MAX(0,Assumptions!I8-Assumptions!$C$9)+Assumptions!I19 | J20: =Assumptions!$C$17+Assumptions!$C$18*MAX(0,Assumptions!J8-Assumptions!$C$9)+Assumptions!J19 | L20: Base + rate slope + competition premium. In 2025 the rate term contributed 1.31pp and competition 2.04pp, on a base of 2.05pp.
B21: Net ASP — realised ($000) | C21: =(Historicals!C18-Historicals!C21*Assumptions!$C$38/100)/C18 | D21: =(Historicals!D18-Historicals!D21*Assumptions!$C$38/100)/D18 | E21: =(Historicals!E18-Historicals!E21*Assumptions!$C$38/100)/E18 | F21: =F19*(1-F20/100) | G21: =G19*(1-G20/100) | H21: =H19*(1-H20/100) | I21: =I19*(1-I20/100) | J21: =J19*(1-J20/100)
B22: Cost per home, ex-charges ($000) | C22: =(Historicals!C26-Historicals!C28-(Historicals!C21-Historicals!C22)*Assumptions!$C$38/100)/C18 | D22: =(Historicals!D26-Historicals!D28-(Historicals!D21-Historicals!D22)*Assumptions!$C$38/100)/D18 | E22: =(Historicals!E26-Historicals!E28-(Historicals!E21-Historicals!E22)*Assumptions!$C$38/100)/E18 | F22: =E22*(1+Assumptions!F27/100) | G22: =F22*(1+Assumptions!G27/100) | H22: =G22*(1+Assumptions!H27/100) | I22: =H22*(1+Assumptions!I27/100) | J22: =I22*(1+Assumptions!J27/100)
B23: Gross profit per home ($000) | C23: =C21-C22 | D23: =D21-D22 | E23: =E21-E22 | F23: =F21-F22 | G23: =G21-G22 | H23: =H21-H22 | I23: =I21-I22 | J23: =J21-J22
B24: Gross margin, ex-charges (%) | C24: =1-C22/C21 | D24: =1-D22/D21 | E24: =1-E22/E21 | F24: =1-F22/F21 | G24: =1-G22/G21 | H24: =1-H22/H21 | I24: =1-I22/I21 | J24: =1-J22/J21
B25: Housing revenue | C25: =C18*C21 | D25: =D18*D21 | E25: =E18*E21 | F25: =F18*F21 | G25: =G18*G21 | H25: =H18*H21 | I25: =I18*I21 | J25: =J18*J21
B27: LAND SALES AND FINANCIAL SERVICES
B28: Land sale revenue | C28: =Historicals!C17+Historicals!C18-C15-C25 | D28: =Historicals!D17+Historicals!D18-D15-D25 | E28: =Historicals!E17+Historicals!E18-E15-E25 | F28: =Assumptions!F30 | G28: =Assumptions!G30 | H28: =Assumptions!H30 | I28: =Assumptions!I30 | J28: =Assumptions!J30
B29: Financial services revenue | C29: =Historicals!C19 | D29: =Historicals!D19 | E29: =Historicals!E19 | F29: =E29*(1+Assumptions!F31/100) | G29: =F29*(1+Assumptions!G31/100) | H29: =G29*(1+Assumptions!H31/100) | I29: =H29*(1+Assumptions!I31/100) | J29: =I29*(1+Assumptions!J31/100)
B31: BUILD-UP TO CONSOLIDATED REVENUE AND COST
B32: Northern segment revenue | C32: =Historicals!C17 | D32: =Historicals!D17 | E32: =Historicals!E17 | F32: =F15+F28*(1-Assumptions!$C$38/100) | G32: =G15+G28*(1-Assumptions!$C$38/100) | H32: =H15+H28*(1-Assumptions!$C$38/100) | I32: =I15+I28*(1-Assumptions!$C$38/100) | J32: =J15+J28*(1-Assumptions!$C$38/100)
B33: Southern segment revenue | C33: =Historicals!C18 | D33: =Historicals!D18 | E33: =Historicals!E18 | F33: =F25+F28*Assumptions!$C$38/100 | G33: =G25+G28*Assumptions!$C$38/100 | H33: =H25+H28*Assumptions!$C$38/100 | I33: =I25+I28*Assumptions!$C$38/100 | J33: =J25+J28*Assumptions!$C$38/100
B34: Total homebuilding revenue | C34: =C32+C33 | D34: =D32+D33 | E34: =E32+E33 | F34: =F32+F33 | G34: =G32+G33 | H34: =H32+H33 | I34: =I32+I33 | J34: =J32+J33
B35: Total revenue | C35: =C34+C29 | D35: =D34+D29 | E35: =E34+E29 | F35: =F34+F29 | G35: =G34+G29 | H35: =H34+H29 | I35: =I34+I29 | J35: =J34+J29
B37: Land and housing costs | C37: =Historicals!C45 | D37: =Historicals!D45 | E37: =Historicals!E45 | F37: =F8*F12+F18*F22+F28*(1-Assumptions!$C$37/100)+Assumptions!F35 | G37: =G8*G12+G18*G22+G28*(1-Assumptions!$C$37/100)+Assumptions!G35 | H37: =H8*H12+H18*H22+H28*(1-Assumptions!$C$37/100)+Assumptions!H35 | I37: =I8*I12+I18*I22+I28*(1-Assumptions!$C$37/100)+Assumptions!I35 | J37: =J8*J12+J18*J22+J28*(1-Assumptions!$C$37/100)+Assumptions!J35
B38: Gross margin — homebuilding (%) | C38: =1-C37/C34 | D38: =1-D37/D34 | E38: =1-E37/E34 | F38: =1-F37/F34 | G38: =1-G37/G34 | H38: =1-H37/H34 | I38: =1-I37/I34 | J38: =1-J37/J34
B39: Gross margin — as reported by MHO (%) | C39: =1-C37/C35 | D39: =1-D37/D35 | E39: =1-E37/E35 | F39: =1-F37/F35 | G39: =1-G37/G35 | H39: =1-H37/H35 | I39: =1-I37/I35 | J39: =1-J37/J35 | L39: Company convention includes financial services revenue in the denominator.
B41: CHECKS — must tie to filed figures for 2023–2025
B42: Total revenue vs 10-K | C42: =C35-Historicals!C20 | D42: =D35-Historicals!D20 | E42: =E35-Historicals!E20
B43: Deliveries vs press release | C43: =C8+C18-Historicals!C10 | D43: =D8+D18-Historicals!D10 | E43: =E8+E18-Historicals!E10

Sheet IS
B2: Income Statement
B3: $ in thousands except per-share amounts. 2023–2025 as filed; 2026E–2030E driven off Segment Build and Assumptions.
B5: ($ in thousands unless noted) | C5: 2023A | D5: 2024A | E5: 2025A | F5: 2026E | G5: 2027E | H5: 2028E | I5: 2029E | J5: 2030E
B7: REVENUE
B8: Northern homebuilding | C8: ='Segment Build'!C32 | D8: ='Segment Build'!D32 | E8: ='Segment Build'!E32 | F8: ='Segment Build'!F32 | G8: ='Segment Build'!G32 | H8: ='Segment Build'!H32 | I8: ='Segment Build'!I32 | J8: ='Segment Build'!J32
B9: Southern homebuilding | C9: ='Segment Build'!C33 | D9: ='Segment Build'!D33 | E9: ='Segment Build'!E33 | F9: ='Segment Build'!F33 | G9: ='Segment Build'!G33 | H9: ='Segment Build'!H33 | I9: ='Segment Build'!I33 | J9: ='Segment Build'!J33
B10: Financial services | C10: ='Segment Build'!C29 | D10: ='Segment Build'!D29 | E10: ='Segment Build'!E29 | F10: ='Segment Build'!F29 | G10: ='Segment Build'!G29 | H10: ='Segment Build'!H29 | I10: ='Segment Build'!I29 | J10: ='Segment Build'!J29
B11: Total revenue | C11: =SUM(C8:C10) | D11: =SUM(D8:D10) | E11: =SUM(E8:E10) | F11: =SUM(F8:F10) | G11: =SUM(G8:G10) | H11: =SUM(H8:H10) | I11: =SUM(I8:I10) | J11: =SUM(J8:J10)
B12: growth (%) | D12: =D11/C11-1 | E12: =E11/D11-1 | F12: =F11/E11-1 | G12: =G11/F11-1 | H12: =H11/G11-1 | I12: =I11/H11-1 | J12: =J11/I11-1
B14: Land and housing costs | C14: ='Segment Build'!C37 | D14: ='Segment Build'!D37 | E14: ='Segment Build'!E37 | F14: ='Segment Build'!F37 | G14: ='Segment Build'!G37 | H14: ='Segment Build'!H37 | I14: ='Segment Build'!I37 | J14: ='Segment Build'!J37
B15: Gross profit | C15: =C11-C14 | D15: =D11-D14 | E15: =E11-E14 | F15: =F11-F14 | G15: =G11-G14 | H15: =H11-H14 | I15: =I11-I14 | J15: =J11-J14
B16: gross margin — as reported (%) | C16: =C15/C11 | D16: =D15/D11 | E16: =E15/E11 | F16: =F15/F11 | G16: =G15/G11 | H16: =H15/H11 | I16: =I15/I11 | J16: =J15/J11
B17: gross margin — homebuilding only (%) | C17: =1-C14/(C8+C9) | D17: =1-D14/(D8+D9) | E17: =1-E14/(E8+E9) | F17: =1-F14/(F8+F9) | G17: =1-G14/(G8+G9) | H17: =1-H14/(H8+H9) | I17: =1-I14/(I8+I9) | J17: =1-J14/(J8+J9)
B19: OPERATING EXPENSES
B20: Selling | C20: =Historicals!C38+Historicals!C39 | D20: =Historicals!D38+Historicals!D39 | E20: =Historicals!E38+Historicals!E39 | F20: =(F8+F9)*Assumptions!F32/100 | G20: =(G8+G9)*Assumptions!G32/100 | H20: =(H8+H9)*Assumptions!H32/100 | I20: =(I8+I9)*Assumptions!I32/100 | J20: =(J8+J9)*Assumptions!J32/100
B21: General and administrative | C21: =Historicals!C40+Historicals!C41+Historicals!C42 | D21: =Historicals!D40+Historicals!D41+Historicals!D42 | E21: =Historicals!E40+Historicals!E41+Historicals!E42 | F21: =(F8+F9)*Assumptions!F33/100+F10*(1-Assumptions!$C$39/100) | G21: =(G8+G9)*Assumptions!G33/100+G10*(1-Assumptions!$C$39/100) | H21: =(H8+H9)*Assumptions!H33/100+H10*(1-Assumptions!$C$39/100) | I21: =(I8+I9)*Assumptions!I33/100+I10*(1-Assumptions!$C$39/100) | J21: =(J8+J9)*Assumptions!J33/100+J10*(1-Assumptions!$C$39/100)
B22: Corporate / unallocated | C22: =-Historicals!C34 | D22: =-Historicals!D34 | E22: =-Historicals!E34 | F22: =-Assumptions!F34 | G22: =-Assumptions!G34 | H22: =-Assumptions!H34 | I22: =-Assumptions!I34 | J22: =-Assumptions!J34
B23: Total operating expenses | C23: =SUM(C20:C22) | D23: =SUM(D20:D22) | E23: =SUM(E20:E22) | F23: =SUM(F20:F22) | G23: =SUM(G20:G22) | H23: =SUM(H20:H22) | I23: =SUM(I20:I22) | J23: =SUM(J20:J22)
B24: SG&A as % of total revenue | C24: =C23/C11 | D24: =D23/D11 | E24: =E23/E11 | F24: =F23/F11 | G24: =G23/G11 | H24: =H23/H11 | I24: =I23/I11 | J24: =J23/J11
B26: OPERATING INCOME | C26: =C15-C23 | D26: =D15-D23 | E26: =E15-E23 | F26: =F15-F23 | G26: =G15-G23 | H26: =H15-H23 | I26: =I15-I23 | J26: =J15-J23
B27: operating margin (%) | C27: =C26/C11 | D27: =D26/D11 | E27: =E26/E11 | F27: =F26/F11 | G27: =G26/G11 | H27: =H26/H11 | I27: =I26/I11 | J27: =J26/J11
B28: Interest income, net of interest expense | C28: =Historicals!C46-Historicals!C35 | D28: =Historicals!D46-Historicals!D35 | E28: =Historicals!E46-Historicals!E35 | F28: =Assumptions!F36 | G28: =Assumptions!G36 | H28: =Assumptions!H36 | I28: =Assumptions!I36 | J28: =Assumptions!J36
B29: Income before income taxes | C29: =C26+C28 | D29: =D26+D28 | E29: =E26+E28 | F29: =F26+F28 | G29: =G26+G28 | H29: =H26+H28 | I29: =I26+I28 | J29: =J26+J28
B30: Provision for income taxes | C30: =Historicals!C47 | D30: =Historicals!D47 | E30: =Historicals!E47 | F30: =F29*Assumptions!$C$40/100 | G30: =G29*Assumptions!$C$40/100 | H30: =H29*Assumptions!$C$40/100 | I30: =I29*Assumptions!$C$40/100 | J30: =J29*Assumptions!$C$40/100
B31: effective tax rate (%) | C31: =C30/C29 | D31: =D30/D29 | E31: =E30/E29 | F31: =F30/F29 | G31: =G30/G29 | H31: =H30/H29 | I31: =I30/I29 | J31: =J30/J29
B32: NET INCOME | C32: =C29-C30 | D32: =D29-D30 | E32: =E29-E30 | F32: =F29-F30 | G32: =G29-G30 | H32: =H29-H30 | I32: =I29-I30 | J32: =J29-J30
B33: net margin (%) | C33: =C32/C11 | D33: =D32/D11 | E33: =E32/E11 | F33: =F32/F11 | G33: =G32/G11 | H33: =H32/H11 | I33: =I32/I11 | J33: =J32/J11
B35: PER SHARE
B36: Diluted weighted-average shares (000) | C36: =Historicals!C50 | D36: =Historicals!D50 | E36: =Historicals!E50 | F36: =E36-Assumptions!F49/Assumptions!F50+Assumptions!F51 | G36: =F36-Assumptions!G49/Assumptions!G50+Assumptions!G51 | H36: =G36-Assumptions!H49/Assumptions!H50+Assumptions!H51 | I36: =H36-Assumptions!I49/Assumptions!I50+Assumptions!I51 | J36: =I36-Assumptions!J49/Assumptions!J50+Assumptions!J51
B37: Diluted EPS ($) | C37: =C32/C36 | D37: =D32/D36 | E37: =E32/E36 | F37: =F32/F36 | G37: =G32/G36 | H37: =H32/H36 | I37: =I32/I36 | J37: =J32/J36
B38: growth (%) | D38: =D37/C37-1 | E38: =E37/D37-1 | F38: =F37/E37-1 | G38: =G37/F37-1 | H38: =H37/G37-1 | I38: =I37/H37-1 | J38: =J37/I37-1
B40: MEMO — SEGMENT OPERATING INCOME
B41: Northern homebuilding | C41: =Historicals!C31 | D41: =Historicals!D31 | E41: =Historicals!E31 | F41: =F8-('Segment Build'!F8*'Segment Build'!F12+'Segment Build'!F28*(1-Assumptions!$C$38/100)*(1-Assumptions!$C$37/100)+Assumptions!F35*0.25)-(F20+(F8+F9)*Assumptions!F33/100)*F8/(F8+F9) | G41: =G8-('Segment Build'!G8*'Segment Build'!G12+'Segment Build'!G28*(1-Assumptions!$C$38/100)*(1-Assumptions!$C$37/100)+Assumptions!G35*0.25)-(G20+(G8+G9)*Assumptions!G33/100)*G8/(G8+G9) | H41: =H8-('Segment Build'!H8*'Segment Build'!H12+'Segment Build'!H28*(1-Assumptions!$C$38/100)*(1-Assumptions!$C$37/100)+Assumptions!H35*0.25)-(H20+(H8+H9)*Assumptions!H33/100)*H8/(H8+H9) | I41: =I8-('Segment Build'!I8*'Segment Build'!I12+'Segment Build'!I28*(1-Assumptions!$C$38/100)*(1-Assumptions!$C$37/100)+Assumptions!I35*0.25)-(I20+(I8+I9)*Assumptions!I33/100)*I8/(I8+I9) | J41: =J8-('Segment Build'!J8*'Segment Build'!J12+'Segment Build'!J28*(1-Assumptions!$C$38/100)*(1-Assumptions!$C$37/100)+Assumptions!J35*0.25)-(J20+(J8+J9)*Assumptions!J33/100)*J8/(J8+J9)
B42: Southern homebuilding | C42: =Historicals!C32 | D42: =Historicals!D32 | E42: =Historicals!E32 | F42: =F9-('Segment Build'!F18*'Segment Build'!F22+'Segment Build'!F28*Assumptions!$C$38/100*(1-Assumptions!$C$37/100)+Assumptions!F35*0.75)-(F20+(F8+F9)*Assumptions!F33/100)*F9/(F8+F9) | G42: =G9-('Segment Build'!G18*'Segment Build'!G22+'Segment Build'!G28*Assumptions!$C$38/100*(1-Assumptions!$C$37/100)+Assumptions!G35*0.75)-(G20+(G8+G9)*Assumptions!G33/100)*G9/(G8+G9) | H42: =H9-('Segment Build'!H18*'Segment Build'!H22+'Segment Build'!H28*Assumptions!$C$38/100*(1-Assumptions!$C$37/100)+Assumptions!H35*0.75)-(H20+(H8+H9)*Assumptions!H33/100)*H9/(H8+H9) | I42: =I9-('Segment Build'!I18*'Segment Build'!I22+'Segment Build'!I28*Assumptions!$C$38/100*(1-Assumptions!$C$37/100)+Assumptions!I35*0.75)-(I20+(I8+I9)*Assumptions!I33/100)*I9/(I8+I9) | J42: =J9-('Segment Build'!J18*'Segment Build'!J22+'Segment Build'!J28*Assumptions!$C$38/100*(1-Assumptions!$C$37/100)+Assumptions!J35*0.75)-(J20+(J8+J9)*Assumptions!J33/100)*J9/(J8+J9)
B43: Financial services | C43: =Historicals!C33 | D43: =Historicals!D33 | E43: =Historicals!E33 | F43: =F10*Assumptions!$C$39/100 | G43: =G10*Assumptions!$C$39/100 | H43: =H10*Assumptions!$C$39/100 | I43: =I10*Assumptions!$C$39/100 | J43: =J10*Assumptions!$C$39/100
B44: Northern operating margin (%) | C44: =C41/C8 | D44: =D41/D8 | E44: =E41/E8 | F44: =F41/F8 | G44: =G41/G8 | H44: =H41/H8 | I44: =I41/I8 | J44: =J41/J8
B45: Southern operating margin (%) | C45: =C42/C9 | D45: =D42/D9 | E45: =E42/E9 | F45: =F42/F9 | G45: =G42/G9 | H45: =H42/H9 | I45: =I42/I9 | J45: =J42/J9 | L45: Base case does NOT restore Southern to its 2024 peak of 18.1%. Getting back there is the bull case, not the base case.

Sheet BS
B2: Balance Sheet
B3: $ in thousands. Cash is driven off the cash flow statement; inventory off turns. The check row at the bottom must read zero in every column.
B5: ($ in thousands unless noted) | C5: 2023A | D5: 2024A | E5: 2025A | F5: 2026E | G5: 2027E | H5: 2028E | I5: 2029E | J5: 2030E
B7: ASSETS
B8: Cash and cash equivalents | C8: =Historicals!C54 | D8: =Historicals!D54 | E8: =Historicals!E54 | F8: =CF!F27 | G8: =CF!G27 | H8: =CF!H27 | I8: =CF!I27 | J8: =CF!J27
B9: Inventory | C9: =Historicals!C55 | D9: =Historicals!D55 | E9: =Historicals!E55 | F9: =MAX('Segment Build'!F34/Assumptions!F43,E9) | G9: =MAX('Segment Build'!G34/Assumptions!G43,F9) | H9: =MAX('Segment Build'!H34/Assumptions!H43,G9) | I9: =MAX('Segment Build'!I34/Assumptions!I43,H9) | J9: =MAX('Segment Build'!J34/Assumptions!J43,I9) | L9: Land, land under development, and homes under construction — 71% of assets and the reason builders trade on book.
B10: Property and equipment, net | C10: =Assumptions!$C$54 | D10: =Assumptions!$C$54 | E10: =Assumptions!$C$54 | F10: =E10+Assumptions!F46-Assumptions!F47 | G10: =F10+Assumptions!G46-Assumptions!G47 | H10: =G10+Assumptions!H46-Assumptions!H47 | I10: =H10+Assumptions!I46-Assumptions!I47 | J10: =I10+Assumptions!J46-Assumptions!J47
B11: Other assets (mortgage loans held for sale, deferred tax, other) | C11: =Historicals!C56-C8-C9-C10 | D11: =Historicals!D56-D8-D9-D10 | E11: =Historicals!E56-E8-E9-E10 | F11: =IS!F11*Assumptions!F44/100 | G11: =IS!G11*Assumptions!G44/100 | H11: =IS!H11*Assumptions!H44/100 | I11: =IS!I11*Assumptions!I44/100 | J11: =IS!J11*Assumptions!J44/100
B12: TOTAL ASSETS | C12: =SUM(C8:C11) | D12: =SUM(D8:D11) | E12: =SUM(E8:E11) | F12: =SUM(F8:F11) | G12: =SUM(G8:G11) | H12: =SUM(H8:H11) | I12: =SUM(I8:I11) | J12: =SUM(J8:J11)
B14: LIABILITIES AND EQUITY
B15: Homebuilding debt (senior notes) | C15: =Historicals!C57 | D15: =Historicals!D57 | E15: =Historicals!E57 | F15: =Assumptions!F52 | G15: =Assumptions!G52 | H15: =Assumptions!H52 | I15: =Assumptions!I52 | J15: =Assumptions!J52
B16: Financial services debt (warehouse facilities) | C16: =Historicals!C58 | D16: =Historicals!D58 | E16: =Historicals!E58 | F16: =Assumptions!F53 | G16: =Assumptions!G53 | H16: =Assumptions!H53 | I16: =Assumptions!I53 | J16: =Assumptions!J53
B17: Accounts payable, accruals, deposits and other | C17: =Historicals!C56-Historicals!C59-C15-C16 | D17: =Historicals!D56-Historicals!D59-D15-D16 | E17: =Historicals!E56-Historicals!E59-E15-E16 | F17: =IS!F11*Assumptions!F45/100 | G17: =IS!G11*Assumptions!G45/100 | H17: =IS!H11*Assumptions!H45/100 | I17: =IS!I11*Assumptions!I45/100 | J17: =IS!J11*Assumptions!J45/100
B18: Total liabilities | C18: =SUM(C15:C17) | D18: =SUM(D15:D17) | E18: =SUM(E15:E17) | F18: =SUM(F15:F17) | G18: =SUM(G15:G17) | H18: =SUM(H15:H17) | I18: =SUM(I15:I17) | J18: =SUM(J15:J17)
B19: Shareholders' equity | C19: =Historicals!C59 | D19: =Historicals!D59 | E19: =Historicals!E59 | F19: =E19+IS!F32+Assumptions!F48-Assumptions!F49 | G19: =F19+IS!G32+Assumptions!G48-Assumptions!G49 | H19: =G19+IS!H32+Assumptions!H48-Assumptions!H49 | I19: =H19+IS!I32+Assumptions!I48-Assumptions!I49 | J19: =I19+IS!J32+Assumptions!J48-Assumptions!J49
B20: TOTAL LIABILITIES AND EQUITY | C20: =C18+C19 | D20: =D18+D19 | E20: =E18+E19 | F20: =F18+F19 | G20: =G18+G19 | H20: =H18+H19 | I20: =I18+I19 | J20: =J18+J19
B21: CHECK — assets less liabilities and equity | C21: =C12-C20 | D21: =D12-D20 | E21: =E12-E20 | F21: =F12-F20 | G21: =G12-G20 | H21: =H12-H20 | I21: =I12-I20 | J21: =J12-J20 | L21: Must be zero. Equity rolls forward from net income, stock comp and buybacks; other liabilities is the revenue-driven line.
B23: CAPITAL STRUCTURE AND RETURNS
B24: Shares outstanding, year end (000) | C24: =Historicals!C51 | D24: =Historicals!D51 | E24: =Historicals!E51 | F24: =IS!F36-600 | G24: =IS!G36-600 | H24: =IS!H36-600 | I24: =IS!I36-600 | J24: =IS!J36-600
B25: Book value per share ($) | C25: =C19/C24 | D25: =D19/D24 | E25: =E19/E24 | F25: =F19/F24 | G25: =G19/G24 | H25: =H19/H24 | I25: =I19/I24 | J25: =J19/J24
B26: Tangible book value per share ($) | C26: =(C19-16100)/C24 | D26: =(D19-16100)/D24 | E26: =(E19-16100)/E24 | F26: =(F19-16100)/F24 | G26: =(G19-16100)/G24 | H26: =(H19-16100)/H24 | I26: =(I19-16100)/I24 | J26: =(J19-16100)/J24 | L26: Goodwill of $16.1m — immaterial, so P/B and P/TB are near-identical for MHO.
B27: Net debt / (net cash) — homebuilding only | C27: =C15-C8 | D27: =D15-D8 | E27: =E15-E8 | F27: =F15-F8 | G27: =G15-G8 | H27: =H15-H8 | I27: =I15-I8 | J27: =J15-J8 | L27: Financial services warehouse debt is excluded: it funds mortgage loans held for sale and is matched by those assets.
B28: Homebuilding debt / total capital (%) | C28: =C15/(C15+C19) | D28: =D15/(D15+D19) | E28: =E15/(E15+E19) | F28: =F15/(F15+F19) | G28: =G15/(G15+G19) | H28: =H15/(H15+H19) | I28: =I15/(I15+I19) | J28: =J15/(J15+J19)
B29: Return on equity (%) | C29: =IS!C32/C19 | D29: =IS!D32/D19 | E29: =IS!E32/E19 | F29: =IS!F32/F19 | G29: =IS!G32/G19 | H29: =IS!H32/H19 | I29: =IS!I32/I19 | J29: =IS!J32/J19 | L29: THE valuation variable. Peer P/B is 96% explained by ROE — see the Comps sheet.
B30: Inventory turns (x) | C30: ='Segment Build'!C34/C9 | D30: ='Segment Build'!D34/D9 | E30: ='Segment Build'!E34/E9 | F30: ='Segment Build'!F34/F9 | G30: ='Segment Build'!G34/G9 | H30: ='Segment Build'!H34/H9 | I30: ='Segment Build'!I34/I9 | J30: ='Segment Build'!J34/J9

Sheet CF
B2: Cash Flow Statement
B3: $ in thousands. 2023–2025 operating cash flow as filed. Projected operating cash flow is built from the balance sheet, which is why growth shows up as a cash cost.
B5: ($ in thousands unless noted) | C5: 2023A | D5: 2024A | E5: 2025A | F5: 2026E | G5: 2027E | H5: 2028E | I5: 2029E | J5: 2030E
B7: OPERATING ACTIVITIES
B8: Net income | C8: =IS!C32 | D8: =IS!D32 | E8: =IS!E32 | F8: =IS!F32 | G8: =IS!G32 | H8: =IS!H32 | I8: =IS!I32 | J8: =IS!J32
B9: Depreciation and amortisation | C9: =Historicals!C61 | D9: =Historicals!D61 | E9: =Historicals!E61 | F9: =Assumptions!F47 | G9: =Assumptions!G47 | H9: =Assumptions!H47 | I9: =Assumptions!I47 | J9: =Assumptions!J47
B10: Stock-based compensation | C10: =Historicals!C62 | D10: =Historicals!D62 | E10: =Historicals!E62 | F10: =Assumptions!F48 | G10: =Assumptions!G48 | H10: =Assumptions!H48 | I10: =Assumptions!I48 | J10: =Assumptions!J48
B11: (Increase) / decrease in inventory | F11: =-(BS!F9-BS!E9) | G11: =-(BS!G9-BS!F9) | H11: =-(BS!H9-BS!G9) | I11: =-(BS!I9-BS!H9) | J11: =-(BS!J9-BS!I9) | L11: Land and work-in-process. This is where the earnings recovery goes.
B12: (Increase) / decrease in other operating assets | F12: =-(BS!F11-BS!E11) | G12: =-(BS!G11-BS!F11) | H12: =-(BS!H11-BS!G11) | I12: =-(BS!I11-BS!H11) | J12: =-(BS!J11-BS!I11)
B13: Increase / (decrease) in other liabilities | F13: =BS!F17-BS!E17 | G13: =BS!G17-BS!F17 | H13: =BS!H17-BS!G17 | I13: =BS!I17-BS!H17 | J13: =BS!J17-BS!I17
B14: CASH FROM OPERATING ACTIVITIES | C14: =Historicals!C60 | D14: =Historicals!D60 | E14: =Historicals!E60 | F14: =SUM(F8:F13) | G14: =SUM(G8:G13) | H14: =SUM(H8:H13) | I14: =SUM(I8:I13) | J14: =SUM(J8:J13)
B16: INVESTING ACTIVITIES
B17: Capital expenditure | C17: =-Historicals!C63 | D17: =-Historicals!D63 | E17: =-Historicals!E63 | F17: =-Assumptions!F46 | G17: =-Assumptions!G46 | H17: =-Assumptions!H46 | I17: =-Assumptions!I46 | J17: =-Assumptions!J46
B18: CASH FROM INVESTING ACTIVITIES | C18: =C17 | D18: =D17 | E18: =E17 | F18: =F17 | G18: =G17 | H18: =H17 | I18: =I17 | J18: =J17
B20: FINANCING ACTIVITIES
B21: Net change in debt | F21: =(BS!F15+BS!F16)-(BS!E15+BS!E16) | G21: =(BS!G15+BS!G16)-(BS!F15+BS!F16) | H21: =(BS!H15+BS!H16)-(BS!G15+BS!G16) | I21: =(BS!I15+BS!I16)-(BS!H15+BS!H16) | J21: =(BS!J15+BS!J16)-(BS!I15+BS!I16)
B22: Share repurchases | C22: =-Historicals!C64 | D22: =-Historicals!D64 | E22: =-Historicals!E64 | F22: =-Assumptions!F49 | G22: =-Assumptions!G49 | H22: =-Assumptions!H49 | I22: =-Assumptions!I49 | J22: =-Assumptions!J49 | L22: $202m in 2025 — 5.4% of the market cap, and the main way shareholders get paid. MHO pays no dividend.
B23: CASH FROM FINANCING ACTIVITIES | F23: =F21+F22 | G23: =G21+G22 | H23: =H21+H22 | I23: =I21+I22 | J23: =J21+J22
B25: Net change in cash | F25: =F14+F18+F23 | G25: =G14+G18+G23 | H25: =H14+H18+H23 | I25: =I14+I18+I23 | J25: =J14+J18+J23
B26: Cash, beginning of period | F26: =Historicals!E54 | G26: =F27 | H26: =G27 | I26: =H27 | J26: =I27
B27: CASH, END OF PERIOD | C27: =Historicals!C54 | D27: =Historicals!D54 | E27: =Historicals!E54 | F27: =F26+F25 | G27: =G26+G25 | H27: =H26+H25 | I27: =I26+I25 | J27: =J26+J25
B29: MEMO — FREE CASH FLOW
B30: Operating cash flow less capex | C30: =C14+C18 | D30: =D14+D18 | E30: =E14+E18 | F30: =F14+F18 | G30: =G14+G18 | H30: =H14+H18 | I30: =I14+I18 | J30: =J14+J18
B31: as % of net income | C31: =C30/C8 | D31: =D30/D8 | E31: =E30/E8 | F31: =F30/F8 | G31: =G30/G8 | H31: =H30/H8 | I31: =I30/I8 | J31: =J30/J8 | L31: Conversion is poor whenever the land pipeline is growing. It was 119% in 2023 when MHO stopped buying land, and 34% in 2025.

Sheet DCF
B2: Discounted Cash Flow
B3: Unlevered free cash flow, valued at 30-Sep-2026 with a mid-year convention. 2026E is included at one quarter (Q4 only).
B5: COST OF CAPITAL
B6: Risk-free rate — 10-yr UST | C6: =Assumptions!$C$57
B7: Equity risk premium | C7: =Assumptions!$C$58
B8: Levered beta | C8: =Assumptions!$C$59
B9: Cost of equity | C9: =C6+C8*C7
B10: Pre-tax cost of debt | C10: =Assumptions!$C$60
B11: After-tax cost of debt | C11: =C10*(1-Assumptions!$C$40/100)
B12: Market capitalisation | C12: =Assumptions!$C$62*Assumptions!$C$63 | L12: Price x shares outstanding.
B13: Homebuilding debt | C13: =BS!E15 | L13: Warehouse debt excluded — it is operating, not capital-structure, debt.
B14: Weight of equity | C14: =C12/(C12+C13)
B15: Weight of debt | C15: =C13/(C12+C13)
B16: WACC | C16: =C14*C9+C15*C11
B17: Terminal growth rate | C17: =Assumptions!$C$61
B19: UNLEVERED FREE CASH FLOW
B20: ($ in thousands) | F20: 2026E | G20: 2027E | H20: 2028E | I20: 2029E | J20: 2030E
B21: EBIT (operating income) | F21: =IS!F26 | G21: =IS!G26 | H21: =IS!H26 | I21: =IS!I26 | J21: =IS!J26
B22: Cash taxes on EBIT | F22: =-F21*Assumptions!$C$40/100 | G22: =-G21*Assumptions!$C$40/100 | H22: =-H21*Assumptions!$C$40/100 | I22: =-I21*Assumptions!$C$40/100 | J22: =-J21*Assumptions!$C$40/100
B23: NOPAT | F23: =F21+F22 | G23: =G21+G22 | H23: =H21+H22 | I23: =I21+I22 | J23: =J21+J22
B24: Add: depreciation and amortisation | F24: =Assumptions!F47 | G24: =Assumptions!G47 | H24: =Assumptions!H47 | I24: =Assumptions!I47 | J24: =Assumptions!J47
B25: Less: capital expenditure | F25: =-Assumptions!F46 | G25: =-Assumptions!G46 | H25: =-Assumptions!H46 | I25: =-Assumptions!I46 | J25: =-Assumptions!J46
B26: Less: stock-based compensation | F26: =-Assumptions!F48 | G26: =-Assumptions!G48 | H26: =-Assumptions!H48 | I26: =-Assumptions!I48 | J26: =-Assumptions!J48 | L26: Treated as a real economic cost. Excluding it would add roughly $6 per share.
B27: Net working capital (inventory + other assets − other liabilities) | E27: =BS!E9+BS!E11-BS!E17 | F27: =BS!F9+BS!F11-BS!F17 | G27: =BS!G9+BS!G11-BS!G17 | H27: =BS!H9+BS!H11-BS!H17 | I27: =BS!I9+BS!I11-BS!I17 | J27: =BS!J9+BS!J11-BS!J17
B28: Less: increase in net working capital | F28: =-(F27-E27) | G28: =-(G27-F27) | H28: =-(H27-G27) | I28: =-(I27-H27) | J28: =-(J27-I27) | L28: The heart of the matter. Land absorbs $185–235m a year once deliveries start growing again.
B29: UNLEVERED FREE CASH FLOW | F29: =F23+F24+F25+F26+F28 | G29: =G23+G24+G25+G26+G28 | H29: =H23+H24+H25+H26+H28 | I29: =I23+I24+I25+I26+I28 | J29: =J23+J24+J25+J26+J28
B30: Period weight (2026E = Q4 only) | F30: 0.25 | G30: 1 | H30: 1 | I30: 1 | J30: 1
B31: Discount period (mid-year) | F31: 0.125 | G31: 0.75 | H31: 1.75 | I31: 2.75 | J31: 3.75
B32: Discount factor | F32: =1/(1+$C$16/100)^F31 | G32: =1/(1+$C$16/100)^G31 | H32: =1/(1+$C$16/100)^H31 | I32: =1/(1+$C$16/100)^I31 | J32: =1/(1+$C$16/100)^J31
B33: Present value of free cash flow | F33: =F29*F30*F32 | G33: =G29*G30*G32 | H33: =H29*H30*H32 | I33: =I29*I30*I32 | J33: =J29*J30*J32
B35: VALUE BRIDGE
B36: Sum of present values, 2026E–2030E | C36: =SUM(F33:J33)
B37: 2030E revenue growth | C37: =IS!J11/IS!I11-1 | L37: The growth the 2030 working capital build actually supports.
B38: Normalised terminal working capital investment | C38: =-J28*(C17/100)/C37 | L38: The 2030 build scaled down to the perpetual growth rate.
B39: NORMALISED TERMINAL FREE CASH FLOW | C39: =J29+(-J28)-C38 | L39: This, not 2030E FCF, is what the terminal value is built on.
B40: Terminal value at 31-Dec-2030 | C40: =C39*(1+C17/100)/(C16/100-C17/100) | L40: Gordon growth on the NORMALISED terminal cash flow.
B41: Present value of terminal value | C41: =C40/(1+C16/100)^4.25
B42: Terminal value as % of enterprise value | C42: =C41/(C36+C41) | L42: High, as it always is for a cyclical with heavy near-term working capital investment. Treat the DCF as a discipline, not an oracle.
B43: ENTERPRISE VALUE | C43: =C36+C41
B44: Less: net debt / (add: net cash) | C44: =BS!E15-737000 | L44: Homebuilding debt $696.9m less cash of $735.9m at 30-Jun-2026: MHO is in a net cash position.
...

Sheet Comps
B2: Comparable Companies
B3: Prices and trailing P/E at 04-Sep-2026 (stockanalysis.com). Equity from each company's most recent 10-Q. Trailing net income is derived from market cap and P/E so that every company is on the same trailing basis.
B5: Company | C5: Price $ | D5: Mkt cap $m | E5: Equity $m | F5: GW+int $m | G5: P/E ttm | H5: Rev ttm $m | I5: NI ttm $m | J5: Shares m | K5: BVPS $ | L5: TBVPS $ | M5: P/B | N5: P/TB | O5: ROE % | P5: P/E x ROE
B6: DHI — D.R. Horton | C6: 137.89 | D6: 38570 | E6: 23820 | F6: 164 | G6: 13.12 | H6: 33350 | I6: =D6/G6 | J6: =D6/C6 | K6: =E6/J6 | L6: =(E6-F6)/J6 | M6: =C6/K6 | N6: =C6/L6 | O6: =I6/E6 | P6: =G6*O6
B7: LEN — Lennar | C7: 79.6 | D7: 19180 | E7: 21621 | F7: 3632 | G7: 12.37 | H7: 32740 | I7: =D7/G7 | J7: =D7/C7 | K7: =E7/J7 | L7: =(E7-F7)/J7 | M7: =C7/K7 | N7: =C7/L7 | O7: =I7/E7 | P7: =G7*O7
