Workbook

Sheet README
B2: M/I Homes (MHO) — Coverage Initiation Model
B3: Three-statement model, DCF and comparable companies analysis. Built 04-Sep-2026.
B5: HOW TO USE THIS WORKBOOK
B6: Colour convention | C6: Blue = hard-coded input. Black = formula. Green = link to another sheet. Yellow = model output. Only blue cells should ever be typed over.
B7: Order of sheets | C7: Assumptions → Historicals → Segment Build → IS → BS → CF → DCF → Comps → Sensitivity → Summary. Everything projected flows from Assumptions.
B8: Where to flex first | C8: Assumptions, the "Southern competition premium" row. That single input carries the thesis. The Sensitivity sheet flexes it against mortgage rates live.
B9: Checks | C9: Segment Build has two tie-out rows against filed revenue and deliveries; BS has an assets-less-liabilities-and-equity check. All must read zero for 2023–2025.
B10: Recalculate | C10: The workbook is written with live formulas but no cached values. Open in Excel and press Ctrl+Alt+F9 (Cmd+Opt+F9 on Mac) for a full rebuild.
B12: SOURCES — every historical figure traces to one of these
B13: FY2025 Form 10-K | C13: Filed 13-Feb-2026, accession 0000799292-26-000006. Segment revenue, land and housing cost, segment operating income and depreciation come from Note 12, "Business Segments".
B14: Q4/FY2025 earnings release | C14: Exhibit 99.1 to Form 8-K filed 28-Jan-2026. Deliveries, new contracts, backlog and average sales price by region.
B15: Q4/FY2024 earnings release | C15: Exhibit 99.1 to Form 8-K filed 29-Jan-2025 (exhibit9914thqtr2024earnin.htm). 2024 and 2023 regional deliveries and contracts.
B16: Q4/FY2023 earnings release | C16: Exhibit 99.1 to Form 8-K filed 31-Jan-2024 (exhibit9914thqtr2023earnin.htm).
B17: Q2 2026 earnings release | C17: Exhibit 99.1 to Form 8-K filed 29-Jul-2026. Used to calibrate the 2026 estimate: 1H revenue $1,984.0m, EPS $5.57, 22.1% reported gross margin, 4,120 deliveries, $459k ASP.
B18: SEC XBRL | C18: data.sec.gov companyfacts, CIK 0000799292, for consolidated income statement, balance sheet and cash flow. Peer equity and net income from the same API.
B19: Rates | C19: FRED. 30-yr fixed mortgage (MORTGAGE30US) 6.71% at 03-Sep-2026; 10-yr UST (DGS10) 4.79%; BB high-yield effective yield (BAMLH0A1HYBBEY) 6.03%.
B20: Housing macro | C20: FRED. Raleigh house price index (ATNHPIUS39580Q) 365.5 → 367.2 over the year to Q2-2026, +0.4%. Charlotte (ATNHPIUS16740Q) +1.1%. NC private building permits (NCBPPRIVSA) declining through 2026.
B21: Prices | C21: stockanalysis.com, 04-Sep-2026 11:44 ET, for MHO and the six comparables.
B23: PROVENANCE — which numbers are facts and which are ours
B24: No company guidance exists | C24: M/I Homes issues no quantitative forward guidance. Neither the FY2025 nor the Q2 2026 release contains a delivery, revenue, margin or EPS target — only safe-harbour boilerplate. Every projected figure in this workbook is the analyst's, not the company's.
B25: Tier 1 — reported fact | C25: All of the Historicals sheet, plus the 1H26 figures used to calibrate 2026. Verified: 42 of 42 consolidated line items match SEC XBRL to the dollar; 24 of 24 segment figures match the 10-K segment note.
B26: Tier 2 — extrapolated from actuals | C26: Cost per home, selling and G&A percentages, corporate expense, tax rate, financial services margin, inventory turns. Each starts from a reported 2025 value and moves on a stated growth rate. Defensible without a view on the world.
B27: Tier 3 — pure judgement, no external anchor | C27: The mortgage rate path, the Southern and Northern competition premiums, delivery growth from 2027, gross ASP growth, and the buyback pace. These are forecasts with nothing behind them but reasoning. The competition premium is the most consequential and the least verifiable.
B28: How much rests on Tier 3 | C28: Of the $2.89 of 2027E EPS growth over 2026E: $1.08 is volume, price, cost and buyback; $0.41 is the mortgage-rate decline; $1.40 — 49% — is the Southern competition premium decaying. Roughly three-fifths of the step-up is Tier 3.
B29: Versus consensus | C29: Four analysts cover MHO. Our 2026E EPS of $11.89 sits marginally below the lowest published estimate ($11.96–$13.34, consensus $12.32–$12.63); 2027E of $14.78 is in the lower half of a $14.24–$16.49 range. Consensus target $170.67, rating Buy.
B31: MODELLING CONVENTIONS AND JUDGEMENT CALLS
B32: Revenue is built by region | C32: Deliveries x average selling price for Northern and Southern separately, never a blended growth rate. The thesis is entirely about regional mix, so a blended rate would assume away the question.
B33: Gross margin is a residual | C33: It is not an input. Incentive load reduces the realised price; cost per home is driven separately; the margin is what is left. That is what actually happens at a closing table.
B34: Incentive load has two terms | C34: A rate term (base + slope x the excess of the mortgage rate over a 5.5% neutral) and a competition premium. The second term is necessary: mortgage rates were flat between 2024 and 2025 while the Southern margin fell 680bp, so rates cannot be the explanation.
B35: Gross margin is shown two ways | C35: MHO reports gross margin on total revenue, which includes financial services revenue carrying no land or housing cost. That flatters the headline by roughly 200bp. The homebuilding-only margin is shown alongside it throughout.
B36: Charges are separated | C36: The $47.7m of 2025 inventory write-offs ($41.0m of it Southern) is stripped out of cost per home and modelled as its own line, so the underlying unit economics are visible.
B37: Financial services debt is excluded from net debt | C37: Warehouse facilities fund mortgage loans held for sale and are matched by those assets. Including them would overstate leverage.
B38: Stock compensation is a real cost | C38: Deducted in the free cash flow build. Adding it back would raise the DCF by roughly $6 per share.
B39: Other liabilities is the revenue-driven line | C39: Accounts payable, accrued compensation, customer deposits and warranty reserve are modelled at 14.4–14.6% of revenue, in line with 2025. The balance sheet ties without a plug.
B41: KNOWN LIMITATIONS — worth saying out loud
B42: Two segments, not seventeen | C42: MHO reports Northern and Southern only. Raleigh and Charlotte cannot be isolated from Florida and Texas in the filings, so "Southern" is the closest proxy for the North Carolina thesis available from public data. Division-level colour would have to come from management.
B43: Financial services is valued inside the consolidated DCF | C43: It is a mortgage origination business with a different risk profile and arguably deserves separate treatment. At 13% of segment operating income the simplification is tolerable, not correct.
B44: Terminal value carries most of the DCF | C44: Roughly three-quarters. That is unavoidable for a cyclical with heavy near-term working capital investment, and it is a reason to weight the DCF at 30% rather than more.
B45: Peer book values are not all the same date | C45: Horton, Lennar and Toll have non-December year ends; each is taken from its most recent 10-Q. The staleness is at most one quarter.
B46: The comp set excludes NVR | C46: Its land-option model produces a structurally different balance sheet and a book multiple that is not comparable.

Sheet Summary
B2: M/I Homes (NYSE: MHO) — Initiation of Coverage
B3: Prepared 04-Sep-2026. All figures traceable to SEC filings; see README for sources.
B5: RECOMMENDATION
B6: Rating | C6: UNDERWEIGHT
B7: 12-month price target ($) | C7: 152 | L7: Weighted across the four methods below. See the note for how the weights were chosen.
B8: Current price ($) | C8: =Assumptions!$C$60
B9: Implied total return (%) | C9: =C7/C8-1 | L9: No dividend. The entire return is price plus the buyback.
B10: Market capitalisation ($m) | C10: =Assumptions!$C$60*Assumptions!$C$61/1000
B12: THE CALL IN ONE PARAGRAPH
B13: North Carolina led the country in net domestic in-migration in the year to July 2025. M/I Homes' Southern segment — which contains
B14: Raleigh and Charlotte — nonetheless saw its operating margin fall from 18.1% to 10.4% in a single year, while the unfashionable Northern
B15: segment held at 14.7%. Mortgage rates were flat across that period, so this was not a rate shock: it was competition for a buyer who could
B16: not afford the house. Cost per home barely moved. The whole margin decline was price given back at the closing table.
B17: MHO is a well-run, net-cash builder buying back 5% of its shares a year, and at 1.16x book it is not expensive. But it now earns roughly
B18: its cost of equity, and peer price-to-book is 96% explained by return on equity. At a 9.7% trailing ROE, the stock is already trading
B19: slightly above what the peer regression says it deserves. We initiate at Neutral: fairly valued, with the margin recovery unpaid for.
B21: VALUATION SUMMARY — where the methods agree and where they do not
B22: Method | C22: Value $ | E22: vs price | G22: Weight | H22: Contribution
B23: Discounted cash flow (rolled forward 12 months) | C23: =DCF!$C$44*(1+DCF!$C$9/100) | E23: =C23/C8-1 | G23: 0.6 | H23: =C23*G23 | L23: What the business earns, and what is left for shareholders after land absorbs its share. Weighted more heavily because it is the only method that prices the return gap.
B24: Peer median P/B on Sep-2027E book | C24: =Comps!H35 | E24: =C24/C8-1 | G24: 0.4 | H24: =C24*G24 | L24: What the market pays other builders for a dollar of book. The multiple comes from the comp set, not from MHO, which is what makes this independent of the DCF and able to disagree with the current price.
B25: Weighted value per share | G25: =SUM(G23:G24) | H25: =SUM(H23:H24)
B26: Cross-check: probability-weighted value (25/50/25 across the scenarios below) | H26: =0.25*F30+0.5*F31+0.25*F32 | L26: Not a second price target — a test of the rating. A probability-weighted value below the share price is what makes this a Sell rather than a Hold.
B28: SCENARIOS
B29: Scenario | C29: 2027E EPS | D29: 2030E EPS | E29: 2028E ROE | F29: Value $ | G29: vs price | L29: What has to be true
B30: Bull | C30: 16.192947 | D30: 26.149131 | E30: 0.12584661 | F30: 205 | G30: =F30/$C$8-1 | L30: Mortgage rates to 5.4% by 2028 and Sunbelt spec supply clears: Southern incentives fall to 4.6pp of price by 2028. Southern operating margin back to 15%.
B31: Base | C31: 14.061193 | D31: 21.156928 | E31: 0.1084713 | F31: 160 | G31: =F31/$C$8-1 | L31: Rates grind to ~6.1%; Southern competition premium halves by 2029 but never disappears. Southern operating margin recovers to 12.9%, not the 18% of 2024.
B32: Bear | C32: 9.529085 | D32: 9.8861663 | E32: 0.066944349 | F32: 95 | G32: =F32/$C$8-1 | L32: Rates hold near 7%; Sunbelt oversupply persists and incentives ratchet to 12pp. Deliveries fall, cost inflation resumes. ROE settles near 6.5% and the stock de-rates to 0.6x book.
B34: KEY FINANCIALS
B35: ($ in millions except per-share) | C35: 2024A | D35: 2025A | E35: 2026E | F35: 2027E | G35: 2028E
B36: Revenue | C36: =IS!D11/1000 | D36: =IS!E11/1000 | E36: =IS!F11/1000 | F36: =IS!G11/1000 | G36: =IS!H11/1000
B37: Homes delivered | C37: ='Segment Build'!D8+'Segment Build'!D18 | D37: ='Segment Build'!E8+'Segment Build'!E18 | E37: ='Segment Build'!F8+'Segment Build'!F18 | F37: ='Segment Build'!G8+'Segment Build'!G18 | G37: ='Segment Build'!H8+'Segment Build'!H18
B38: Gross margin — homebuilding (%) | C38: =1-IS!D14/(IS!D8+IS!D9) | D38: =1-IS!E14/(IS!E8+IS!E9) | E38: =1-IS!F14/(IS!F8+IS!F9) | F38: =1-IS!G14/(IS!G8+IS!G9) | G38: =1-IS!H14/(IS!H8+IS!H9)
B39: Operating margin (%) | C39: =IS!D26/IS!D11 | D39: =IS!E26/IS!E11 | E39: =IS!F26/IS!F11 | F39: =IS!G26/IS!G11 | G39: =IS!H26/IS!H11
B40: Southern operating margin (%) | C40: =IS!D42/IS!D9 | D40: =IS!E42/IS!E9 | E40: =IS!F42/IS!F9 | F40: =IS!G42/IS!G9 | G40: =IS!H42/IS!H9
B41: Northern operating margin (%) | C41: =IS!D41/IS!D8 | D41: =IS!E41/IS!E8 | E41: =IS!F41/IS!F8 | F41: =IS!G41/IS!G8 | G41: =IS!H41/IS!H8
B42: Diluted EPS ($) | C42: =IS!D37 | D42: =IS!E37 | E42: =IS!F37 | F42: =IS!G37 | G42: =IS!H37
B43: Book value per share ($) | C43: =BS!D25 | D43: =BS!E25 | E43: =BS!F25 | F43: =BS!G25 | G43: =BS!H25
B44: Return on equity (%) | C44: =BS!D29 | D44: =BS!E29 | E44: =BS!F29 | F44: =BS!G29 | G44: =BS!H29
B45: Net debt / (net cash) | C45: =BS!D27/1000 | D45: =BS!E27/1000 | E45: =BS!F27/1000 | F45: =BS!G27/1000 | G45: =BS!H27/1000

Sheet Assumptions
B2: Assumptions & Drivers
B3: Blue = hard-coded input. Every projected line in this model traces back to this sheet. Flex the incentive block first — it is where the thesis lives.
B5: DRIVER | C5: 2023A | D5: 2024A | E5: 2025A | F5: 2026E | G5: 2027E | H5: 2028E | I5: 2029E | J5: 2030E
B7: MACRO
B8: 30-yr fixed mortgage rate (annual avg, %) | C8: 6.81 | D8: 6.8 | E8: 6.72 | F8: 6.65 | G8: 6.35 | H8: 6.1 | I8: 5.95 | J8: 5.9 | L8: 2023–25 actual (FRED MORTGAGE30US annual avg). 2026E+ forecast. Spot = 6.71% at 03-Sep-2026.
B9: Neutral mortgage rate (%) | C9: 5.5 | L9: Rate at which a builder needs no abnormal incentive. Single input — applies to all years.
B11: INCENTIVE INTENSITY — incentive load (% of gross ASP) = base + rate slope x (mortgage rate − neutral) + competition premium
B12: Northern — base incentive (% of gross ASP) | C12: 0.939
B13: Northern — rate slope (pp per 100bp above neutral) | C13: 0.9
B14: Northern — competition premium (pp) | C14: 0 | D14: 0 | E14: 1.209 | F14: 3.51 | G14: 3.15 | H14: 2.9 | I14: 2.75 | J14: 2.65 | L14: Incentive over and above what the rate alone justifies. Zero through 2025 by construction — the Northern margin held.
B15: Southern — base incentive (% of gross ASP) | C15: 1.944
B16: Southern — rate slope (pp per 100bp above neutral) | C16: 1.2
B17: Southern — competition premium (pp) | C17: 0 | D17: 0 | E17: 1.972 | F17: 4.371 | G17: 3.75 | H17: 3.3 | I17: 3 | J17: 2.8 | L17: THE KEY INPUT. 3.6pp in 2025 and 6.0pp in 2026E: mortgage rates were flat 2024→2025, so the Southern margin collapse is a supply/competition event, not a rate event. Flex this before anything else.
B19: VOLUME, PRICE AND COST (growth rates, % — projections only)
B20: Deliveries growth — Northern (%) | F20: -3.9 | G20: 3.5 | H20: 4 | I20: 3.25 | J20: 3
B21: Deliveries growth — Southern (%) | F21: -4.3 | G21: 5 | H21: 5.5 | I21: 4.25 | J21: 4
B22: Gross ASP growth — Northern (%) | F22: 1 | G22: 2 | H22: 2.25 | I22: 2.5 | J22: 2.5 | L22: Gross ASP = list price before incentives.
B23: Gross ASP growth — Southern (%) | F23: -1.5 | G23: 1 | H23: 2 | I23: 2.25 | J23: 2.25
B24: Cost per home growth — Northern (%) | F24: 0 | G24: 2.2 | H24: 2.4 | I24: 2.5 | J24: 2.5
B25: Cost per home growth — Southern (%) | F25: -0.3 | G25: 2 | H25: 2.3 | I25: 2.5 | J25: 2.5 | L25: Land + stick-and-brick + closing cost per unit delivered.
B27: OTHER INCOME STATEMENT DRIVERS
B28: Land sale revenue ($000) | F28: 22000 | G28: 24000 | H28: 26000 | I28: 28000 | J28: 30000
B29: Financial services revenue growth (%) | F29: 1.5 | G29: 5 | H29: 5.5 | I29: 4.5 | J29: 4.5
B30: Selling expense (% of homebuilding revenue) | F30: 6.2 | G30: 6 | H30: 5.8 | I30: 5.7 | J30: 5.65
B31: Homebuilding G&A (% of homebuilding revenue) | F31: 2.8 | G31: 2.72 | H31: 2.66 | I31: 2.63 | J31: 2.6
B32: Corporate / unallocated ($000) | F32: -93000 | G32: -96500 | H32: -100500 | I32: -104500 | J32: -108500 | L32: Not charged to either region in the 10-K segment note; averaged −$85m over 2023–25.
B33: Inventory impairment & write-offs ($000) | F33: 16000 | G33: 9000 | H33: 7000 | I33: 7000 | J33: 7000 | L33: $47.7m in 2025, of which $41.0m Southern.
B34: Net interest income ($000) | F34: 18000 | G34: 16000 | H34: 15000 | I34: 15000 | J34: 16000
B35: Land sale gross margin (%) | C35: 7
B36: Share of land revenue in Southern (%) | C36: 65
B37: Financial services pre-tax margin (%) | C37: 54.5 | L37: 54.3% in 2025 (op income $68.2m on revenue $125.5m).
B38: Effective tax rate (%) | C38: 23.5 | L38: 23.5% vs 23.5% in 2025; energy-efficiency credits keep it below statutory + state.
B40: BALANCE SHEET & CASH FLOW DRIVERS
B41: Inventory turns (homebuilding revenue / ending inventory) | F41: 1.2 | G41: 1.22 | H41: 1.24 | I41: 1.25 | J41: 1.26 | L41: 1.27x in 2025. Falls in 2026E as deliveries drop faster than the land pipeline.
B42: Other operating assets (% of revenue) | F42: 14.3 | G42: 14.25 | H42: 14.2 | I42: 14.15 | J42: 14.1
B43: Other liabilities (% of revenue) | F43: 14.45 | G43: 14.5 | H43: 14.55 | I43: 14.55 | J43: 14.55 | L43: A/P, accrued comp, customer deposits, warranty reserve. 14.4% in 2025.
B44: Capital expenditure ($000) | F44: 11000 | G44: 11500 | H44: 12000 | I44: 12500 | J44: 13000
B45: Depreciation & amortisation ($000) | F45: 20000 | G45: 21000 | H45: 22000 | I45: 23000 | J45: 24000
B46: Stock-based compensation ($000) | F46: 17500 | G46: 18000 | H46: 18500 | I46: 19000 | J46: 19500
B47: Share repurchase ($000) | F47: 185000 | G47: 185000 | H47: 185000 | I47: 185000 | J47: 185000 | L47: $202m in 2025, $177m in 2024. Assumes management sustains the pace.
...

Sheet Historicals
B2: Historicals — as reported
B3: Hand-entered from the FY2025 10-K (filed 13-Feb-2026) and the Q4 earnings releases. Nothing on this sheet is calculated except the check rows. Source for each block in column L.
B5: ($ in thousands unless noted) | C5: 2023A | D5: 2024A | E5: 2025A | F5: 2026E | G5: 2027E | H5: 2028E | I5: 2029E | J5: 2030E
B7: OPERATING — by region [FY2025 10-K MD&A; Q4 earnings releases 2024–2026]
B8: Homes delivered — Northern | C8: 3169 | D8: 3873 | E8: 3716 | L8: FY25 rel. p.6 / FY24 rel. / FY23 rel.
B9: Homes delivered — Southern | C9: 4943 | D9: 5182 | E9: 5205
B10: Homes delivered — total | C10: =C8+C9 | D10: =D8+D9 | E10: =E8+E9 | L10: Ties to 8,112 / 9,055 / 8,921 as reported.
B11: New contracts — Northern | C11: 3361 | D11: 3761 | E11: 3416
B12: New contracts — Southern | C12: 4616 | D12: 4823 | E12: 4783
B13: Backlog units — year end | C13: 3002 | D13: 2531 | E13: 1809 | L13: 3,002 / 2,531 / 1,809 — down 40% over two years.
B14: Active communities | D14: 220 | E14: 232
B16: SEGMENT REVENUE [FY2025 10-K, Note 12 “Business Segments”]
B17: Northern homebuilding | C17: 1523943 | D17: 1900013 | E17: 1890457 | L17: FY2025 10-K, Note 12 Business Segments (R84) - filed 2026-02-13, acc 0000799292-26-000006
B18: Southern homebuilding | C18: 2415730 | D18: 2488451 | E18: 2401861
B19: Financial services | C19: 93829 | D19: 116206 | E19: 125463
B20: Total revenue | C20: =SUM(C17:C19) | D20: =SUM(D17:D19) | E20: =SUM(E17:E19) | L20: Ties to $4,033.5m / $4,504.7m / $4,417.8m as reported.
B22: SEGMENT LAND & HOUSING COST
B23: Northern | C23: 1228949 | D23: 1480326 | E23: 1475438
B24: Southern | C24: 1785624 | D24: 1825455 | E24: 1925144
B25: of which: inventory write-offs — Northern | C25: 0 | D25: 0 | E25: 6700 | L25: 2025 total valuation adjustments $47.7m.
B26: of which: inventory write-offs — Southern | C26: 0 | D26: 0 | E26: 41000
B28: SEGMENT OPERATING INCOME
B29: Northern homebuilding | C29: 176320 | D29: 281099 | E29: 278056
B30: Southern homebuilding | C30: 440168 | D30: 450598 | E30: 249969
B31: Financial services | C31: 48714 | D31: 63380 | E31: 68160
B32: Corporate / unallocated | C32: =Historicals!C33-C29-C30-C31 | D32: =Historicals!D33-D29-D30-D31 | E32: =Historicals!E33-E29-E30-E31
B33: Total operating income | C33: 587222 | D33: 706094 | E33: 506553
B35: SEGMENT SELLING AND G&A
B36: Selling — Northern | C36: 81847 | D36: 95680 | E36: 95860
B37: Selling — Southern | C37: 124860 | D37: 136198 | E37: 149457
B38: G&A — Northern | C38: 36827 | D38: 42908 | E38: 41103
B39: G&A — Southern | C39: 65078 | D39: 76200 | E39: 77291
B40: G&A — Financial services | C40: 45115 | D40: 52826 | E40: 57303
B42: CONSOLIDATED INCOME STATEMENT [FY2025 10-K; XBRL companyfacts CIK 0000799292]
B43: Land and housing costs | C43: 3014573 | D43: 3305781 | E43: 3400582
B44: Income before income taxes | C44: 607277 | D44: 733608 | E44: 526588
B45: Provision for income taxes | C45: 141912 | D45: 169883 | E45: 123647
B46: Net income | C46: 465365 | D46: 563725 | E46: 402941
B47: Diluted EPS ($) | C47: 16.21 | D47: 19.71 | E47: 14.74
B48: Diluted weighted-average shares (000) | C48: 28716 | D48: 28600 | E48: 27338
...

Sheet Segment Build
B2: Segment Build — deliveries x ASP, and the incentive bridge to gross margin
B3: Revenue is built region by region, never off a blended growth rate. Gross margin falls out of the arithmetic: incentives cut the price, costs do not move, so the margin is the residual.
B5: ($ in thousands unless noted) | C5: 2023A | D5: 2024A | E5: 2025A | F5: 2026E | G5: 2027E | H5: 2028E | I5: 2029E | J5: 2030E
B7: NORTHERN HOMEBUILDING — Columbus, Cincinnati, Indianapolis, Chicago, Minneapolis, Detroit
B8: Homes delivered | C8: =Historicals!C8 | D8: =Historicals!D8 | E8: =Historicals!E8 | F8: =E8*(1+Assumptions!F20/100) | G8: =F8*(1+Assumptions!G20/100) | H8: =G8*(1+Assumptions!H20/100) | I8: =H8*(1+Assumptions!I20/100) | J8: =I8*(1+Assumptions!J20/100)
B9: Gross ASP — list price before incentives ($000) | C9: =C11/(1-C10/100) | D9: =D11/(1-D10/100) | E9: =E11/(1-E10/100) | F9: =E9*(1+Assumptions!F22/100) | G9: =F9*(1+Assumptions!G22/100) | H9: =G9*(1+Assumptions!H22/100) | I9: =H9*(1+Assumptions!I22/100) | J9: =I9*(1+Assumptions!J22/100)
B10: Incentive load (% of gross ASP) | C10: =Assumptions!$C$12+Assumptions!$C$13*MAX(0,Assumptions!C8-Assumptions!$C$9)+Assumptions!C14 | D10: =Assumptions!$C$12+Assumptions!$C$13*MAX(0,Assumptions!D8-Assumptions!$C$9)+Assumptions!D14 | E10: =Assumptions!$C$12+Assumptions!$C$13*MAX(0,Assumptions!E8-Assumptions!$C$9)+Assumptions!E14 | F10: =Assumptions!$C$12+Assumptions!$C$13*MAX(0,Assumptions!F8-Assumptions!$C$9)+Assumptions!F14 | G10: =Assumptions!$C$12+Assumptions!$C$13*MAX(0,Assumptions!G8-Assumptions!$C$9)+Assumptions!G14 | H10: =Assumptions!$C$12+Assumptions!$C$13*MAX(0,Assumptions!H8-Assumptions!$C$9)+Assumptions!H14 | I10: =Assumptions!$C$12+Assumptions!$C$13*MAX(0,Assumptions!I8-Assumptions!$C$9)+Assumptions!I14 | J10: =Assumptions!$C$12+Assumptions!$C$13*MAX(0,Assumptions!J8-Assumptions!$C$9)+Assumptions!J14 | L10: Rate-driven only through 2025.
B11: Net ASP — realised ($000) | C11: =Historicals!C17/C8 | D11: =Historicals!D17/D8 | E11: =Historicals!E17/E8 | F11: =F9*(1-F10/100) | G11: =G9*(1-G10/100) | H11: =H9*(1-H10/100) | I11: =I9*(1-I10/100) | J11: =J9*(1-J10/100)
B12: Cost per home, ex-charges ($000) | C12: =(Historicals!C23-Historicals!C25)/C8 | D12: =(Historicals!D23-Historicals!D25)/D8 | E12: =(Historicals!E23-Historicals!E25)/E8 | F12: =E12*(1+Assumptions!F24/100) | G12: =F12*(1+Assumptions!G24/100) | H12: =G12*(1+Assumptions!H24/100) | I12: =H12*(1+Assumptions!I24/100) | J12: =I12*(1+Assumptions!J24/100)
B13: Gross profit per home ($000) | C13: =C11-C12 | D13: =D11-D12 | E13: =E11-E12 | F13: =F11-F12 | G13: =G11-G12 | H13: =H11-H12 | I13: =I11-I12 | J13: =J11-J12
B14: Gross margin, ex-charges (%) | C14: =1-C12/C11 | D14: =1-D12/D11 | E14: =1-E12/E11 | F14: =1-F12/F11 | G14: =1-G12/G11 | H14: =1-H12/H11 | I14: =1-I12/I11 | J14: =1-J12/J11
B15: Housing revenue | C15: =C8*C11 | D15: =D8*D11 | E15: =E8*E11 | F15: =F8*F11 | G15: =G8*G11 | H15: =H8*H11 | I15: =I8*I11 | J15: =J8*J11
B17: SOUTHERN HOMEBUILDING — Tampa, Orlando, Sarasota, Fort Myers, CHARLOTTE, RALEIGH, Houston, San Antonio, Austin, Dallas, Nashville
B18: Homes delivered | C18: =Historicals!C9 | D18: =Historicals!D9 | E18: =Historicals!E9 | F18: =E18*(1+Assumptions!F21/100) | G18: =F18*(1+Assumptions!G21/100) | H18: =G18*(1+Assumptions!H21/100) | I18: =H18*(1+Assumptions!I21/100) | J18: =I18*(1+Assumptions!J21/100)
B19: Gross ASP — list price before incentives ($000) | C19: =C21/(1-C20/100) | D19: =D21/(1-D20/100) | E19: =E21/(1-E20/100) | F19: =E19*(1+Assumptions!F23/100) | G19: =F19*(1+Assumptions!G23/100) | H19: =G19*(1+Assumptions!H23/100) | I19: =H19*(1+Assumptions!I23/100) | J19: =I19*(1+Assumptions!J23/100)
B20: Incentive load (% of gross ASP) | C20: =Assumptions!$C$15+Assumptions!$C$16*MAX(0,Assumptions!C8-Assumptions!$C$9)+Assumptions!C17 | D20: =Assumptions!$C$15+Assumptions!$C$16*MAX(0,Assumptions!D8-Assumptions!$C$9)+Assumptions!D17 | E20: =Assumptions!$C$15+Assumptions!$C$16*MAX(0,Assumptions!E8-Assumptions!$C$9)+Assumptions!E17 | F20: =Assumptions!$C$15+Assumptions!$C$16*MAX(0,Assumptions!F8-Assumptions!$C$9)+Assumptions!F17 | G20: =Assumptions!$C$15+Assumptions!$C$16*MAX(0,Assumptions!G8-Assumptions!$C$9)+Assumptions!G17 | H20: =Assumptions!$C$15+Assumptions!$C$16*MAX(0,Assumptions!H8-Assumptions!$C$9)+Assumptions!H17 | I20: =Assumptions!$C$15+Assumptions!$C$16*MAX(0,Assumptions!I8-Assumptions!$C$9)+Assumptions!I17 | J20: =Assumptions!$C$15+Assumptions!$C$16*MAX(0,Assumptions!J8-Assumptions!$C$9)+Assumptions!J17 | L20: Base + rate slope + competition premium. In 2025 the rate term contributed 4.5pp and competition 3.6pp.
B21: Net ASP — realised ($000) | C21: =Historicals!C18/C18 | D21: =Historicals!D18/D18 | E21: =Historicals!E18/E18 | F21: =F19*(1-F20/100) | G21: =G19*(1-G20/100) | H21: =H19*(1-H20/100) | I21: =I19*(1-I20/100) | J21: =J19*(1-J20/100)
B22: Cost per home, ex-charges ($000) | C22: =(Historicals!C24-Historicals!C26)/C18 | D22: =(Historicals!D24-Historicals!D26)/D18 | E22: =(Historicals!E24-Historicals!E26)/E18 | F22: =E22*(1+Assumptions!F25/100) | G22: =F22*(1+Assumptions!G25/100) | H22: =G22*(1+Assumptions!H25/100) | I22: =H22*(1+Assumptions!I25/100) | J22: =I22*(1+Assumptions!J25/100)
B23: Gross profit per home ($000) | C23: =C21-C22 | D23: =D21-D22 | E23: =E21-E22 | F23: =F21-F22 | G23: =G21-G22 | H23: =H21-H22 | I23: =I21-I22 | J23: =J21-J22
B24: Gross margin, ex-charges (%) | C24: =1-C22/C21 | D24: =1-D22/D21 | E24: =1-E22/E21 | F24: =1-F22/F21 | G24: =1-G22/G21 | H24: =1-H22/H21 | I24: =1-I22/I21 | J24: =1-J22/J21
B25: Housing revenue | C25: =C18*C21 | D25: =D18*D21 | E25: =E18*E21 | F25: =F18*F21 | G25: =G18*G21 | H25: =H18*H21 | I25: =I18*I21 | J25: =J18*J21
B27: LAND SALES AND FINANCIAL SERVICES
B28: Land sale revenue | C28: =Historicals!C17+Historicals!C18-C15-C25 | D28: =Historicals!D17+Historicals!D18-D15-D25 | E28: =Historicals!E17+Historicals!E18-E15-E25 | F28: =Assumptions!F28 | G28: =Assumptions!G28 | H28: =Assumptions!H28 | I28: =Assumptions!I28 | J28: =Assumptions!J28
B29: Financial services revenue | C29: =Historicals!C19 | D29: =Historicals!D19 | E29: =Historicals!E19 | F29: =E29*(1+Assumptions!F29/100) | G29: =F29*(1+Assumptions!G29/100) | H29: =G29*(1+Assumptions!H29/100) | I29: =H29*(1+Assumptions!I29/100) | J29: =I29*(1+Assumptions!J29/100)
B31: BUILD-UP TO CONSOLIDATED REVENUE AND COST
B32: Northern segment revenue | C32: =Historicals!C17 | D32: =Historicals!D17 | E32: =Historicals!E17 | F32: =F15+F28*(1-Assumptions!$C$36/100) | G32: =G15+G28*(1-Assumptions!$C$36/100) | H32: =H15+H28*(1-Assumptions!$C$36/100) | I32: =I15+I28*(1-Assumptions!$C$36/100) | J32: =J15+J28*(1-Assumptions!$C$36/100)
B33: Southern segment revenue | C33: =Historicals!C18 | D33: =Historicals!D18 | E33: =Historicals!E18 | F33: =F25+F28*Assumptions!$C$36/100 | G33: =G25+G28*Assumptions!$C$36/100 | H33: =H25+H28*Assumptions!$C$36/100 | I33: =I25+I28*Assumptions!$C$36/100 | J33: =J25+J28*Assumptions!$C$36/100
B34: Total homebuilding revenue | C34: =C32+C33 | D34: =D32+D33 | E34: =E32+E33 | F34: =F32+F33 | G34: =G32+G33 | H34: =H32+H33 | I34: =I32+I33 | J34: =J32+J33
B35: Total revenue | C35: =C34+C29 | D35: =D34+D29 | E35: =E34+E29 | F35: =F34+F29 | G35: =G34+G29 | H35: =H34+H29 | I35: =I34+I29 | J35: =J34+J29
B37: Land and housing costs | C37: =Historicals!C43 | D37: =Historicals!D43 | E37: =Historicals!E43 | F37: =F8*F12+F18*F22+F28*(1-Assumptions!$C$35/100)+Assumptions!F33 | G37: =G8*G12+G18*G22+G28*(1-Assumptions!$C$35/100)+Assumptions!G33 | H37: =H8*H12+H18*H22+H28*(1-Assumptions!$C$35/100)+Assumptions!H33 | I37: =I8*I12+I18*I22+I28*(1-Assumptions!$C$35/100)+Assumptions!I33 | J37: =J8*J12+J18*J22+J28*(1-Assumptions!$C$35/100)+Assumptions!J33
B38: Gross margin — homebuilding (%) | C38: =1-C37/C34 | D38: =1-D37/D34 | E38: =1-E37/E34 | F38: =1-F37/F34 | G38: =1-G37/G34 | H38: =1-H37/H34 | I38: =1-I37/I34 | J38: =1-J37/J34
B39: Gross margin — as reported by MHO (%) | C39: =1-C37/C35 | D39: =1-D37/D35 | E39: =1-E37/E35 | F39: =1-F37/F35 | G39: =1-G37/G35 | H39: =1-H37/H35 | I39: =1-I37/I35 | J39: =1-J37/J35 | L39: Company convention includes financial services revenue in the denominator.
B41: CHECKS — must tie to filed figures for 2023–2025
B42: Total revenue vs 10-K | C42: =C35-Historicals!C20 | D42: =D35-Historicals!D20 | E42: =E35-Historicals!E20
B43: Deliveries vs press release | C43: =C8+C18-Historicals!C10 | D43: =D8+D18-Historicals!D10 | E43: =E8+E18-Historicals!E10

Sheet IS
B2: Income Statement
B3: $ in thousands except per-share amounts. 2023–2025 as filed; 2026E–2030E driven off Segment Build and Assumptions.
B5: ($ in thousands unless noted) | C5: 2023A | D5: 2024A | E5: 2025A | F5: 2026E | G5: 2027E | H5: 2028E | I5: 2029E | J5: 2030E
B7: REVENUE
B8: Northern homebuilding | C8: ='Segment Build'!C32 | D8: ='Segment Build'!D32 | E8: ='Segment Build'!E32 | F8: ='Segment Build'!F32 | G8: ='Segment Build'!G32 | H8: ='Segment Build'!H32 | I8: ='Segment Build'!I32 | J8: ='Segment Build'!J32
B9: Southern homebuilding | C9: ='Segment Build'!C33 | D9: ='Segment Build'!D33 | E9: ='Segment Build'!E33 | F9: ='Segment Build'!F33 | G9: ='Segment Build'!G33 | H9: ='Segment Build'!H33 | I9: ='Segment Build'!I33 | J9: ='Segment Build'!J33
B10: Financial services | C10: ='Segment Build'!C29 | D10: ='Segment Build'!D29 | E10: ='Segment Build'!E29 | F10: ='Segment Build'!F29 | G10: ='Segment Build'!G29 | H10: ='Segment Build'!H29 | I10: ='Segment Build'!I29 | J10: ='Segment Build'!J29
B11: Total revenue | C11: =SUM(C8:C10) | D11: =SUM(D8:D10) | E11: =SUM(E8:E10) | F11: =SUM(F8:F10) | G11: =SUM(G8:G10) | H11: =SUM(H8:H10) | I11: =SUM(I8:I10) | J11: =SUM(J8:J10)
B12: growth (%) | D12: =D11/C11-1 | E12: =E11/D11-1 | F12: =F11/E11-1 | G12: =G11/F11-1 | H12: =H11/G11-1 | I12: =I11/H11-1 | J12: =J11/I11-1
B14: Land and housing costs | C14: ='Segment Build'!C37 | D14: ='Segment Build'!D37 | E14: ='Segment Build'!E37 | F14: ='Segment Build'!F37 | G14: ='Segment Build'!G37 | H14: ='Segment Build'!H37 | I14: ='Segment Build'!I37 | J14: ='Segment Build'!J37
B15: Gross profit | C15: =C11-C14 | D15: =D11-D14 | E15: =E11-E14 | F15: =F11-F14 | G15: =G11-G14 | H15: =H11-H14 | I15: =I11-I14 | J15: =J11-J14
B16: gross margin — as reported (%) | C16: =C15/C11 | D16: =D15/D11 | E16: =E15/E11 | F16: =F15/F11 | G16: =G15/G11 | H16: =H15/H11 | I16: =I15/I11 | J16: =J15/J11
B17: gross margin — homebuilding only (%) | C17: =1-C14/(C8+C9) | D17: =1-D14/(D8+D9) | E17: =1-E14/(E8+E9) | F17: =1-F14/(F8+F9) | G17: =1-G14/(G8+G9) | H17: =1-H14/(H8+H9) | I17: =1-I14/(I8+I9) | J17: =1-J14/(J8+J9)
B19: OPERATING EXPENSES
B20: Selling | C20: =Historicals!C36+Historicals!C37 | D20: =Historicals!D36+Historicals!D37 | E20: =Historicals!E36+Historicals!E37 | F20: =(F8+F9)*Assumptions!F30/100 | G20: =(G8+G9)*Assumptions!G30/100 | H20: =(H8+H9)*Assumptions!H30/100 | I20: =(I8+I9)*Assumptions!I30/100 | J20: =(J8+J9)*Assumptions!J30/100
B21: General and administrative | C21: =Historicals!C38+Historicals!C39+Historicals!C40 | D21: =Historicals!D38+Historicals!D39+Historicals!D40 | E21: =Historicals!E38+Historicals!E39+Historicals!E40 | F21: =(F8+F9)*Assumptions!F31/100+F10*(1-Assumptions!$C$37/100) | G21: =(G8+G9)*Assumptions!G31/100+G10*(1-Assumptions!$C$37/100) | H21: =(H8+H9)*Assumptions!H31/100+H10*(1-Assumptions!$C$37/100) | I21: =(I8+I9)*Assumptions!I31/100+I10*(1-Assumptions!$C$37/100) | J21: =(J8+J9)*Assumptions!J31/100+J10*(1-Assumptions!$C$37/100)
B22: Corporate / unallocated | C22: =-Historicals!C32 | D22: =-Historicals!D32 | E22: =-Historicals!E32 | F22: =-Assumptions!F32 | G22: =-Assumptions!G32 | H22: =-Assumptions!H32 | I22: =-Assumptions!I32 | J22: =-Assumptions!J32
B23: Total operating expenses | C23: =SUM(C20:C22) | D23: =SUM(D20:D22) | E23: =SUM(E20:E22) | F23: =SUM(F20:F22) | G23: =SUM(G20:G22) | H23: =SUM(H20:H22) | I23: =SUM(I20:I22) | J23: =SUM(J20:J22)
B24: SG&A as % of total revenue | C24: =C23/C11 | D24: =D23/D11 | E24: =E23/E11 | F24: =F23/F11 | G24: =G23/G11 | H24: =H23/H11 | I24: =I23/I11 | J24: =J23/J11
B26: OPERATING INCOME | C26: =C15-C23 | D26: =D15-D23 | E26: =E15-E23 | F26: =F15-F23 | G26: =G15-G23 | H26: =H15-H23 | I26: =I15-I23 | J26: =J15-J23
B27: operating margin (%) | C27: =C26/C11 | D27: =D26/D11 | E27: =E26/E11 | F27: =F26/F11 | G27: =G26/G11 | H27: =H26/H11 | I27: =I26/I11 | J27: =J26/J11
B28: Interest income, net of interest expense | C28: =Historicals!C44-Historicals!C33 | D28: =Historicals!D44-Historicals!D33 | E28: =Historicals!E44-Historicals!E33 | F28: =Assumptions!F34 | G28: =Assumptions!G34 | H28: =Assumptions!H34 | I28: =Assumptions!I34 | J28: =Assumptions!J34
B29: Income before income taxes | C29: =C26+C28 | D29: =D26+D28 | E29: =E26+E28 | F29: =F26+F28 | G29: =G26+G28 | H29: =H26+H28 | I29: =I26+I28 | J29: =J26+J28
B30: Provision for income taxes | C30: =Historicals!C45 | D30: =Historicals!D45 | E30: =Historicals!E45 | F30: =F29*Assumptions!$C$38/100 | G30: =G29*Assumptions!$C$38/100 | H30: =H29*Assumptions!$C$38/100 | I30: =I29*Assumptions!$C$38/100 | J30: =J29*Assumptions!$C$38/100
B31: effective tax rate (%) | C31: =C30/C29 | D31: =D30/D29 | E31: =E30/E29 | F31: =F30/F29 | G31: =G30/G29 | H31: =H30/H29 | I31: =I30/I29 | J31: =J30/J29
B32: NET INCOME | C32: =C29-C30 | D32: =D29-D30 | E32: =E29-E30 | F32: =F29-F30 | G32: =G29-G30 | H32: =H29-H30 | I32: =I29-I30 | J32: =J29-J30
B33: net margin (%) | C33: =C32/C11 | D33: =D32/D11 | E33: =E32/E11 | F33: =F32/F11 | G33: =G32/G11 | H33: =H32/H11 | I33: =I32/I11 | J33: =J32/J11
B35: PER SHARE
B36: Diluted weighted-average shares (000) | C36: =Historicals!C48 | D36: =Historicals!D48 | E36: =Historicals!E48 | F36: =E36-Assumptions!F47/Assumptions!F48+Assumptions!F49 | G36: =F36-Assumptions!G47/Assumptions!G48+Assumptions!G49 | H36: =G36-Assumptions!H47/Assumptions!H48+Assumptions!H49 | I36: =H36-Assumptions!I47/Assumptions!I48+Assumptions!I49 | J36: =I36-Assumptions!J47/Assumptions!J48+Assumptions!J49
B37: Diluted EPS ($) | C37: =C32/C36 | D37: =D32/D36 | E37: =E32/E36 | F37: =F32/F36 | G37: =G32/G36 | H37: =H32/H36 | I37: =I32/I36 | J37: =J32/J36
B38: growth (%) | D38: =D37/C37-1 | E38: =E37/D37-1 | F38: =F37/E37-1 | G38: =G37/F37-1 | H38: =H37/G37-1 | I38: =I37/H37-1 | J38: =J37/I37-1
B40: MEMO — SEGMENT OPERATING INCOME
B41: Northern homebuilding | C41: =Historicals!C29 | D41: =Historicals!D29 | E41: =Historicals!E29 | F41: =F8-('Segment Build'!F8*'Segment Build'!F12+'Segment Build'!F28*(1-Assumptions!$C$36/100)*(1-Assumptions!$C$35/100)+Assumptions!F33*0.25)-(F20+(F8+F9)*Assumptions!F31/100)*F8/(F8+F9) | G41: =G8-('Segment Build'!G8*'Segment Build'!G12+'Segment Build'!G28*(1-Assumptions!$C$36/100)*(1-Assumptions!$C$35/100)+Assumptions!G33*0.25)-(G20+(G8+G9)*Assumptions!G31/100)*G8/(G8+G9) | H41: =H8-('Segment Build'!H8*'Segment Build'!H12+'Segment Build'!H28*(1-Assumptions!$C$36/100)*(1-Assumptions!$C$35/100)+Assumptions!H33*0.25)-(H20+(H8+H9)*Assumptions!H31/100)*H8/(H8+H9) | I41: =I8-('Segment Build'!I8*'Segment Build'!I12+'Segment Build'!I28*(1-Assumptions!$C$36/100)*(1-Assumptions!$C$35/100)+Assumptions!I33*0.25)-(I20+(I8+I9)*Assumptions!I31/100)*I8/(I8+I9) | J41: =J8-('Segment Build'!J8*'Segment Build'!J12+'Segment Build'!J28*(1-Assumptions!$C$36/100)*(1-Assumptions!$C$35/100)+Assumptions!J33*0.25)-(J20+(J8+J9)*Assumptions!J31/100)*J8/(J8+J9)
B42: Southern homebuilding | C42: =Historicals!C30 | D42: =Historicals!D30 | E42: =Historicals!E30 | F42: =F9-('Segment Build'!F18*'Segment Build'!F22+'Segment Build'!F28*Assumptions!$C$36/100*(1-Assumptions!$C$35/100)+Assumptions!F33*0.75)-(F20+(F8+F9)*Assumptions!F31/100)*F9/(F8+F9) | G42: =G9-('Segment Build'!G18*'Segment Build'!G22+'Segment Build'!G28*Assumptions!$C$36/100*(1-Assumptions!$C$35/100)+Assumptions!G33*0.75)-(G20+(G8+G9)*Assumptions!G31/100)*G9/(G8+G9) | H42: =H9-('Segment Build'!H18*'Segment Build'!H22+'Segment Build'!H28*Assumptions!$C$36/100*(1-Assumptions!$C$35/100)+Assumptions!H33*0.75)-(H20+(H8+H9)*Assumptions!H31/100)*H9/(H8+H9) | I42: =I9-('Segment Build'!I18*'Segment Build'!I22+'Segment Build'!I28*Assumptions!$C$36/100*(1-Assumptions!$C$35/100)+Assumptions!I33*0.75)-(I20+(I8+I9)*Assumptions!I31/100)*I9/(I8+I9) | J42: =J9-('Segment Build'!J18*'Segment Build'!J22+'Segment Build'!J28*Assumptions!$C$36/100*(1-Assumptions!$C$35/100)+Assumptions!J33*0.75)-(J20+(J8+J9)*Assumptions!J31/100)*J9/(J8+J9)
B43: Financial services | C43: =Historicals!C31 | D43: =Historicals!D31 | E43: =Historicals!E31 | F43: =F10*Assumptions!$C$37/100 | G43: =G10*Assumptions!$C$37/100 | H43: =H10*Assumptions!$C$37/100 | I43: =I10*Assumptions!$C$37/100 | J43: =J10*Assumptions!$C$37/100
B44: Northern operating margin (%) | C44: =C41/C8 | D44: =D41/D8 | E44: =E41/E8 | F44: =F41/F8 | G44: =G41/G8 | H44: =H41/H8 | I44: =I41/I8 | J44: =J41/J8
B45: Southern operating margin (%) | C45: =C42/C9 | D45: =D42/D9 | E45: =E42/E9 | F45: =F42/F9 | G45: =G42/G9 | H45: =H42/H9 | I45: =I42/I9 | J45: =J42/J9 | L45: Base case does NOT restore Southern to its 2024 peak of 18.1%. Getting back there is the bull case, not the base case.

Sheet BS
B2: Balance Sheet
B3: $ in thousands. Cash is driven off the cash flow statement; inventory off turns. The check row at the bottom must read zero in every column.
B5: ($ in thousands unless noted) | C5: 2023A | D5: 2024A | E5: 2025A | F5: 2026E | G5: 2027E | H5: 2028E | I5: 2029E | J5: 2030E
B7: ASSETS
B8: Cash and cash equivalents | C8: =Historicals!C52 | D8: =Historicals!D52 | E8: =Historicals!E52 | F8: =CF!F27 | G8: =CF!G27 | H8: =CF!H27 | I8: =CF!I27 | J8: =CF!J27
B9: Inventory | C9: =Historicals!C53 | D9: =Historicals!D53 | E9: =Historicals!E53 | F9: ='Segment Build'!F34/Assumptions!F41 | G9: ='Segment Build'!G34/Assumptions!G41 | H9: ='Segment Build'!H34/Assumptions!H41 | I9: ='Segment Build'!I34/Assumptions!I41 | J9: ='Segment Build'!J34/Assumptions!J41 | L9: Land, land under development, and homes under construction — 71% of assets and the reason builders trade on book.
B10: Property and equipment, net | C10: =Assumptions!$C$52 | D10: =Assumptions!$C$52 | E10: =Assumptions!$C$52 | F10: =E10+Assumptions!F44-Assumptions!F45 | G10: =F10+Assumptions!G44-Assumptions!G45 | H10: =G10+Assumptions!H44-Assumptions!H45 | I10: =H10+Assumptions!I44-Assumptions!I45 | J10: =I10+Assumptions!J44-Assumptions!J45
B11: Other assets (mortgage loans held for sale, deferred tax, other) | C11: =Historicals!C54-C8-C9-C10 | D11: =Historicals!D54-D8-D9-D10 | E11: =Historicals!E54-E8-E9-E10 | F11: =IS!F11*Assumptions!F42/100 | G11: =IS!G11*Assumptions!G42/100 | H11: =IS!H11*Assumptions!H42/100 | I11: =IS!I11*Assumptions!I42/100 | J11: =IS!J11*Assumptions!J42/100
B12: TOTAL ASSETS | C12: =SUM(C8:C11) | D12: =SUM(D8:D11) | E12: =SUM(E8:E11) | F12: =SUM(F8:F11) | G12: =SUM(G8:G11) | H12: =SUM(H8:H11) | I12: =SUM(I8:I11) | J12: =SUM(J8:J11)
B14: LIABILITIES AND EQUITY
B15: Homebuilding debt (senior notes) | C15: =Historicals!C55 | D15: =Historicals!D55 | E15: =Historicals!E55 | F15: =Assumptions!F50 | G15: =Assumptions!G50 | H15: =Assumptions!H50 | I15: =Assumptions!I50 | J15: =Assumptions!J50
B16: Financial services debt (warehouse facilities) | C16: =Historicals!C56 | D16: =Historicals!D56 | E16: =Historicals!E56 | F16: =Assumptions!F51 | G16: =Assumptions!G51 | H16: =Assumptions!H51 | I16: =Assumptions!I51 | J16: =Assumptions!J51
B17: Accounts payable, accruals, deposits and other | C17: =Historicals!C54-Historicals!C57-C15-C16 | D17: =Historicals!D54-Historicals!D57-D15-D16 | E17: =Historicals!E54-Historicals!E57-E15-E16 | F17: =IS!F11*Assumptions!F43/100 | G17: =IS!G11*Assumptions!G43/100 | H17: =IS!H11*Assumptions!H43/100 | I17: =IS!I11*Assumptions!I43/100 | J17: =IS!J11*Assumptions!J43/100
B18: Total liabilities | C18: =SUM(C15:C17) | D18: =SUM(D15:D17) | E18: =SUM(E15:E17) | F18: =SUM(F15:F17) | G18: =SUM(G15:G17) | H18: =SUM(H15:H17) | I18: =SUM(I15:I17) | J18: =SUM(J15:J17)
B19: Shareholders' equity | C19: =Historicals!C57 | D19: =Historicals!D57 | E19: =Historicals!E57 | F19: =E19+IS!F32+Assumptions!F46-Assumptions!F47 | G19: =F19+IS!G32+Assumptions!G46-Assumptions!G47 | H19: =G19+IS!H32+Assumptions!H46-Assumptions!H47 | I19: =H19+IS!I32+Assumptions!I46-Assumptions!I47 | J19: =I19+IS!J32+Assumptions!J46-Assumptions!J47
B20: TOTAL LIABILITIES AND EQUITY | C20: =C18+C19 | D20: =D18+D19 | E20: =E18+E19 | F20: =F18+F19 | G20: =G18+G19 | H20: =H18+H19 | I20: =I18+I19 | J20: =J18+J19
B21: CHECK — assets less liabilities and equity | C21: =C12-C20 | D21: =D12-D20 | E21: =E12-E20 | F21: =F12-F20 | G21: =G12-G20 | H21: =H12-H20 | I21: =I12-I20 | J21: =J12-J20 | L21: Must be zero. Equity rolls forward from net income, stock comp and buybacks; other liabilities is the revenue-driven line.
B23: CAPITAL STRUCTURE AND RETURNS
B24: Shares outstanding, year end (000) | C24: =Historicals!C49 | D24: =Historicals!D49 | E24: =Historicals!E49 | F24: =IS!F36-600 | G24: =IS!G36-600 | H24: =IS!H36-600 | I24: =IS!I36-600 | J24: =IS!J36-600
B25: Book value per share ($) | C25: =C19/C24 | D25: =D19/D24 | E25: =E19/E24 | F25: =F19/F24 | G25: =G19/G24 | H25: =H19/H24 | I25: =I19/I24 | J25: =J19/J24
B26: Tangible book value per share ($) | C26: =(C19-16100)/C24 | D26: =(D19-16100)/D24 | E26: =(E19-16100)/E24 | F26: =(F19-16100)/F24 | G26: =(G19-16100)/G24 | H26: =(H19-16100)/H24 | I26: =(I19-16100)/I24 | J26: =(J19-16100)/J24 | L26: Goodwill of $16.1m — immaterial, so P/B and P/TB are near-identical for MHO.
B27: Net debt / (net cash) — homebuilding only | C27: =C15-C8 | D27: =D15-D8 | E27: =E15-E8 | F27: =F15-F8 | G27: =G15-G8 | H27: =H15-H8 | I27: =I15-I8 | J27: =J15-J8 | L27: Financial services warehouse debt is excluded: it funds mortgage loans held for sale and is matched by those assets.
B28: Homebuilding debt / total capital (%) | C28: =C15/(C15+C19) | D28: =D15/(D15+D19) | E28: =E15/(E15+E19) | F28: =F15/(F15+F19) | G28: =G15/(G15+G19) | H28: =H15/(H15+H19) | I28: =I15/(I15+I19) | J28: =J15/(J15+J19)
B29: Return on equity (%) | C29: =IS!C32/C19 | D29: =IS!D32/D19 | E29: =IS!E32/E19 | F29: =IS!F32/F19 | G29: =IS!G32/G19 | H29: =IS!H32/H19 | I29: =IS!I32/I19 | J29: =IS!J32/J19 | L29: THE valuation variable. Peer P/B is 96% explained by ROE — see the Comps sheet.
B30: Inventory turns (x) | C30: ='Segment Build'!C34/C9 | D30: ='Segment Build'!D34/D9 | E30: ='Segment Build'!E34/E9 | F30: ='Segment Build'!F34/F9 | G30: ='Segment Build'!G34/G9 | H30: ='Segment Build'!H34/H9 | I30: ='Segment Build'!I34/I9 | J30: ='Segment Build'!J34/J9

Sheet CF
B2: Cash Flow Statement
B3: $ in thousands. 2023–2025 operating cash flow as filed. Projected operating cash flow is built from the balance sheet, which is why growth shows up as a cash cost.
B5: ($ in thousands unless noted) | C5: 2023A | D5: 2024A | E5: 2025A | F5: 2026E | G5: 2027E | H5: 2028E | I5: 2029E | J5: 2030E
B7: OPERATING ACTIVITIES
B8: Net income | C8: =IS!C32 | D8: =IS!D32 | E8: =IS!E32 | F8: =IS!F32 | G8: =IS!G32 | H8: =IS!H32 | I8: =IS!I32 | J8: =IS!J32
B9: Depreciation and amortisation | C9: =Historicals!C59 | D9: =Historicals!D59 | E9: =Historicals!E59 | F9: =Assumptions!F45 | G9: =Assumptions!G45 | H9: =Assumptions!H45 | I9: =Assumptions!I45 | J9: =Assumptions!J45
B10: Stock-based compensation | C10: =Historicals!C60 | D10: =Historicals!D60 | E10: =Historicals!E60 | F10: =Assumptions!F46 | G10: =Assumptions!G46 | H10: =Assumptions!H46 | I10: =Assumptions!I46 | J10: =Assumptions!J46
B11: (Increase) / decrease in inventory | F11: =-(BS!F9-BS!E9) | G11: =-(BS!G9-BS!F9) | H11: =-(BS!H9-BS!G9) | I11: =-(BS!I9-BS!H9) | J11: =-(BS!J9-BS!I9) | L11: Land and work-in-process. This is where the earnings recovery goes.
B12: (Increase) / decrease in other operating assets | F12: =-(BS!F11-BS!E11) | G12: =-(BS!G11-BS!F11) | H12: =-(BS!H11-BS!G11) | I12: =-(BS!I11-BS!H11) | J12: =-(BS!J11-BS!I11)
B13: Increase / (decrease) in other liabilities | F13: =BS!F17-BS!E17 | G13: =BS!G17-BS!F17 | H13: =BS!H17-BS!G17 | I13: =BS!I17-BS!H17 | J13: =BS!J17-BS!I17
B14: CASH FROM OPERATING ACTIVITIES | C14: =Historicals!C58 | D14: =Historicals!D58 | E14: =Historicals!E58 | F14: =SUM(F8:F13) | G14: =SUM(G8:G13) | H14: =SUM(H8:H13) | I14: =SUM(I8:I13) | J14: =SUM(J8:J13)
B16: INVESTING ACTIVITIES
B17: Capital expenditure | C17: =-Historicals!C61 | D17: =-Historicals!D61 | E17: =-Historicals!E61 | F17: =-Assumptions!F44 | G17: =-Assumptions!G44 | H17: =-Assumptions!H44 | I17: =-Assumptions!I44 | J17: =-Assumptions!J44
B18: CASH FROM INVESTING ACTIVITIES | C18: =C17 | D18: =D17 | E18: =E17 | F18: =F17 | G18: =G17 | H18: =H17 | I18: =I17 | J18: =J17
B20: FINANCING ACTIVITIES
B21: Net change in debt | F21: =(BS!F15+BS!F16)-(BS!E15+BS!E16) | G21: =(BS!G15+BS!G16)-(BS!F15+BS!F16) | H21: =(BS!H15+BS!H16)-(BS!G15+BS!G16) | I21: =(BS!I15+BS!I16)-(BS!H15+BS!H16) | J21: =(BS!J15+BS!J16)-(BS!I15+BS!I16)
B22: Share repurchases | C22: =-Historicals!C62 | D22: =-Historicals!D62 | E22: =-Historicals!E62 | F22: =-Assumptions!F47 | G22: =-Assumptions!G47 | H22: =-Assumptions!H47 | I22: =-Assumptions!I47 | J22: =-Assumptions!J47 | L22: $202m in 2025 — 5.4% of the market cap, and the main way shareholders get paid. MHO pays no dividend.
B23: CASH FROM FINANCING ACTIVITIES | F23: =F21+F22 | G23: =G21+G22 | H23: =H21+H22 | I23: =I21+I22 | J23: =J21+J22
B25: Net change in cash | F25: =F14+F18+F23 | G25: =G14+G18+G23 | H25: =H14+H18+H23 | I25: =I14+I18+I23 | J25: =J14+J18+J23
B26: Cash, beginning of period | F26: =Historicals!E52 | G26: =F27 | H26: =G27 | I26: =H27 | J26: =I27
B27: CASH, END OF PERIOD | C27: =Historicals!C52 | D27: =Historicals!D52 | E27: =Historicals!E52 | F27: =F26+F25 | G27: =G26+G25 | H27: =H26+H25 | I27: =I26+I25 | J27: =J26+J25
B29: MEMO — FREE CASH FLOW
B30: Operating cash flow less capex | C30: =C14+C18 | D30: =D14+D18 | E30: =E14+E18 | F30: =F14+F18 | G30: =G14+G18 | H30: =H14+H18 | I30: =I14+I18 | J30: =J14+J18
B31: as % of net income | C31: =C30/C8 | D31: =D30/D8 | E31: =E30/E8 | F31: =F30/F8 | G31: =G30/G8 | H31: =H30/H8 | I31: =I30/I8 | J31: =J30/J8 | L31: Conversion is poor whenever the land pipeline is growing. It was 119% in 2023 when MHO stopped buying land, and 34% in 2025.

Sheet DCF
B2: Discounted Cash Flow
B3: Unlevered free cash flow, valued at 30-Sep-2026 with a mid-year convention. 2026E is included at one quarter (Q4 only).
B5: COST OF CAPITAL
B6: Risk-free rate — 10-yr UST | C6: =Assumptions!$C$55
B7: Equity risk premium | C7: =Assumptions!$C$56
B8: Levered beta | C8: =Assumptions!$C$57
B9: Cost of equity | C9: =C6+C8*C7
B10: Pre-tax cost of debt | C10: =Assumptions!$C$58
B11: After-tax cost of debt | C11: =C10*(1-Assumptions!$C$38/100)
B12: Market capitalisation | C12: =Assumptions!$C$60*Assumptions!$C$61 | L12: Price x shares outstanding.
B13: Homebuilding debt | C13: =BS!E15 | L13: Warehouse debt excluded — it is operating, not capital-structure, debt.
B14: Weight of equity | C14: =C12/(C12+C13)
B15: Weight of debt | C15: =C13/(C12+C13)
B16: WACC | C16: =C14*C9+C15*C11
B17: Terminal growth rate | C17: =Assumptions!$C$59
B19: UNLEVERED FREE CASH FLOW
B20: ($ in thousands) | F20: 2026E | G20: 2027E | H20: 2028E | I20: 2029E | J20: 2030E
B21: EBIT (operating income) | F21: =IS!F26 | G21: =IS!G26 | H21: =IS!H26 | I21: =IS!I26 | J21: =IS!J26
B22: Cash taxes on EBIT | F22: =-F21*Assumptions!$C$38/100 | G22: =-G21*Assumptions!$C$38/100 | H22: =-H21*Assumptions!$C$38/100 | I22: =-I21*Assumptions!$C$38/100 | J22: =-J21*Assumptions!$C$38/100
B23: NOPAT | F23: =F21+F22 | G23: =G21+G22 | H23: =H21+H22 | I23: =I21+I22 | J23: =J21+J22
B24: Add: depreciation and amortisation | F24: =Assumptions!F45 | G24: =Assumptions!G45 | H24: =Assumptions!H45 | I24: =Assumptions!I45 | J24: =Assumptions!J45
B25: Less: capital expenditure | F25: =-Assumptions!F44 | G25: =-Assumptions!G44 | H25: =-Assumptions!H44 | I25: =-Assumptions!I44 | J25: =-Assumptions!J44
B26: Less: stock-based compensation | F26: =-Assumptions!F46 | G26: =-Assumptions!G46 | H26: =-Assumptions!H46 | I26: =-Assumptions!I46 | J26: =-Assumptions!J46 | L26: Treated as a real economic cost. Excluding it would add roughly $6 per share.
B27: Net working capital (inventory + other assets − other liabilities) | E27: =BS!E9+BS!E11-BS!E17 | F27: =BS!F9+BS!F11-BS!F17 | G27: =BS!G9+BS!G11-BS!G17 | H27: =BS!H9+BS!H11-BS!H17 | I27: =BS!I9+BS!I11-BS!I17 | J27: =BS!J9+BS!J11-BS!J17
B28: Less: increase in net working capital | F28: =-(F27-E27) | G28: =-(G27-F27) | H28: =-(H27-G27) | I28: =-(I27-H27) | J28: =-(J27-I27) | L28: The heart of the matter. Land absorbs $185–235m a year once deliveries start growing again.
B29: UNLEVERED FREE CASH FLOW | F29: =F23+F24+F25+F26+F28 | G29: =G23+G24+G25+G26+G28 | H29: =H23+H24+H25+H26+H28 | I29: =I23+I24+I25+I26+I28 | J29: =J23+J24+J25+J26+J28
B30: Period weight (2026E = Q4 only) | F30: 0.25 | G30: 1 | H30: 1 | I30: 1 | J30: 1
B31: Discount period (mid-year) | F31: 0.125 | G31: 0.75 | H31: 1.75 | I31: 2.75 | J31: 3.75
B32: Discount factor | F32: =1/(1+$C$16/100)^F31 | G32: =1/(1+$C$16/100)^G31 | H32: =1/(1+$C$16/100)^H31 | I32: =1/(1+$C$16/100)^I31 | J32: =1/(1+$C$16/100)^J31
B33: Present value of free cash flow | F33: =F29*F30*F32 | G33: =G29*G30*G32 | H33: =H29*H30*H32 | I33: =I29*I30*I32 | J33: =J29*J30*J32
B35: VALUE BRIDGE
B36: Sum of present values, 2026E–2030E | C36: =SUM(F33:J33)
B37: Terminal value at 31-Dec-2030 | C37: =J29*(1+C17/100)/(C16/100-C17/100) | L37: Gordon growth on 2030E free cash flow.
B38: Present value of terminal value | C38: =C37/(1+C16/100)^4.25
B39: Terminal value as % of enterprise value | C39: =C38/(C36+C38) | L39: High, as it always is for a cyclical with heavy near-term working capital investment. Treat the DCF as a discipline, not an oracle.
B40: ENTERPRISE VALUE | C40: =C36+C38
B41: Less: net debt / (add: net cash) | C41: =BS!E15-737000 | L41: Homebuilding debt $696.9m less cash of $735.9m at 30-Jun-2026: MHO is in a net cash position.
B42: EQUITY VALUE | C42: =C40-C41
B43: Shares outstanding (000) | C43: =Assumptions!$C$61
B44: DCF VALUE PER SHARE | C44: =C42/C43
...

Sheet Comps
B2: Comparable Companies
B3: Prices and trailing P/E at 04-Sep-2026 (stockanalysis.com). Equity from each company's most recent 10-Q. Trailing net income is derived from market cap and P/E so that every company is on the same trailing basis.
B5: Company | C5: Price $ | D5: Mkt cap $m | E5: Equity $m | F5: GW+int $m | G5: P/E ttm | H5: Rev ttm $m | I5: NI ttm $m | J5: Shares m | K5: BVPS $ | L5: TBVPS $ | M5: P/B | N5: P/TB | O5: ROE % | P5: P/E x ROE
B6: DHI — D.R. Horton | C6: 142.94 | D6: 39980 | E6: 23820 | F6: 164 | G6: 13.6 | H6: 33350 | I6: =D6/G6 | J6: =D6/C6 | K6: =E6/J6 | L6: =(E6-F6)/J6 | M6: =C6/K6 | N6: =C6/L6 | O6: =I6/E6 | P6: =G6*O6
B7: LEN — Lennar | C7: 83.88 | D7: 20210 | E7: 21621 | F7: 3632 | G7: 13.12 | H7: 32740 | I7: =D7/G7 | J7: =D7/C7 | K7: =E7/J7 | L7: =(E7-F7)/J7 | M7: =C7/K7 | N7: =C7/L7 | O7: =I7/E7 | P7: =G7*O7
B8: PHM — PulteGroup | C8: 124.36 | D8: 23310 | E8: 13014 | F8: 86 | G8: 12.68 | H8: 16410 | I8: =D8/G8 | J8: =D8/C8 | K8: =E8/J8 | L8: =(E8-F8)/J8 | M8: =C8/K8 | N8: =C8/L8 | O8: =I8/E8 | P8: =G8*O8
B9: TOL — Toll Brothers | C9: 141.43 | D9: 13030 | E9: 8531 | F9: 0 | G9: 11.32 | H9: 10760 | I9: =D9/G9 | J9: =D9/C9 | K9: =E9/J9 | L9: =(E9-F9)/J9 | M9: =C9/K9 | N9: =C9/L9 | O9: =I9/E9 | P9: =G9*O9
B10: MTH — Meritage | C10: 67.75 | D10: 4420 | E10: 5058 | F10: 34 | G10: 14.07 | H10: 5390 | I10: =D10/G10 | J10: =D10/C10 | K10: =E10/J10 | L10: =(E10-F10)/J10 | M10: =C10/K10 | N10: =C10/L10 | O10: =I10/E10 | P10: =G10*O10
B11: TPH — Tri Pointe | C11: 46.95 | D11: 4000 | E11: 3141 | F11: 156 | G11: 22.24 | H11: 3250 | I11: =D11/G11 | J11: =D11/C11 | K11: =E11/J11 | L11: =(E11-F11)/J11 | M11: =C11/K11 | N11: =C11/L11 | O11: =I11/E11 | P11: =G11*O11
B12: Peer median | G12: =MEDIAN(G6:G11) | M12: =MEDIAN(M6:M11) | N12: =MEDIAN(N6:N11) | O12: =MEDIAN(O6:O11)
B13: Peer mean | G13: =AVERAGE(G6:G11) | M13: =AVERAGE(M6:M11) | N13: =AVERAGE(N6:N11) | O13: =AVERAGE(O6:O11)
B14: MHO — M/I Homes | C14: 148.26 | D14: 3748 | E14: 3227 | F14: 16 | G14: 12.41 | H14: 4260 | I14: =D14/G14 | J14: =D14/C14 | K14: =E14/J14 | L14: =(E14-F14)/J14 | M14: =C14/K14 | N14: =C14/L14 | O14: =I14/E14 | P14: =G14*O14 | Q14: MHO screens ~17% below the peer median on P/B — but it also earns a lower return on that book than any peer except the two trading below book.
B16: WHAT THE COMP SET ACTUALLY SHOWS
B17: P/B = (MktCap/NI) x (NI/Equity) = P/E x ROE. That is an accounting identity, not an empirical result — the P/E x ROE column above reproduces P/B exactly for every company.
B18: So there is no independent information in a fitted line through P/B and ROE, and none is attempted here. The observation that survives is about DISPERSION: peer earnings
B19: multiples sit in a narrow band while returns on equity do not. The market is paying similar earnings multiples for very different returns on capital.
B20: The practical consequence: P/B and P/E are ONE view of this stock, not two, so they are counted once. And because the multiple barely moves with the return, MHO's
B21: depressed ROE shows up in the earnings rather than in the multiple — which is why the peer-based valuation below simply applies the peer median P/E to our own EPS estimate.
B23: DISPERSION — peer earnings multiples vs peer returns (Tri Pointe shown but excluded: its 22x P/E reflects trough earnings)
B24: Peer P/E — low | E24: =MIN(G6:G10)
B25: Peer P/E — high | E25: =MAX(G6:G10)
B26: Peer P/E — coefficient of variation | E26: =STDEVP(G6:G10)/AVERAGE(G6:G10) | Q26: Earnings multiples are tightly clustered.
B27: Peer ROE — low | E27: =MIN(O6:O10)
B28: Peer ROE — high | E28: =MAX(O6:O10)
B29: Peer ROE — coefficient of variation | E29: =STDEVP(O6:O10)/AVERAGE(O6:O10) | Q29: Returns vary roughly four times as much as the multiples that price them.
B31: Normalised ROE implied by the current share price | E31: =3.5+M14*(DCF!$C$9-3.5) | Q31: At an 11.5% cost of equity and 3.5% long-run growth, a 1.16x book multiple already pays for a normalised return on equity of roughly 12.8%. The base case reaches 12.2% by 2029, so the recovery is largely in the price.
B33: IMPLIED VALUE PER SHARE
B34: Method | C34: Multiple | E34: Applied to | H34: Value $
B35: Peer median P/B on Sep-2027E book | C35: =M12 | E35: Book value at Sep-2027 (est.) | H35: =C35*((BS!F25)+(BS!G25))/2 | Q35: THE comparables method. The median multiple the comp set trades at, applied to our own book estimate. Scenarios instead take the multiple the market puts on the builder actually earning that return — Meritage for the bear case, Toll Brothers for the bull — so every multiple in the model belongs to a company you can look up.
B36: Memo: peer median P/E on 2027E EPS | C36: =G12 | E36: 2027E diluted EPS | H36: =C36*IS!G37 | Q36: Cross-check only, NOT weighted. The identity P/B = P/E x ROE means this is the same view restated.
B37: Memo: MHO's own P/E on 2027E EPS | C37: =G14 | E37: 2027E diluted EPS | H37: =C37*IS!G37 | Q37: NOT a valuation. This reduces algebraically to today's share price scaled by our own EPS growth, so it cannot disagree with the market. Shown only to document why it is not used.

Sheet Sensitivity
B2: Sensitivity — mortgage rates and incentive load
B3: Live formulas, not pasted values. Every cell re-runs the 2027E P&L from gross ASP down to EPS, holding 2026E at base. Change anything on Assumptions and this grid moves.
B5: 2027E INPUTS HELD CONSTANT (linked — do not overwrite)
B6: Deliveries — Northern | C6: ='Segment Build'!G8
B7: Deliveries — Southern | C7: ='Segment Build'!G18
B8: Gross ASP — Northern ($000) | C8: ='Segment Build'!G9
B9: Gross ASP — Southern ($000) | C9: ='Segment Build'!G19
B10: Cost per home — Northern ($000) | C10: ='Segment Build'!G12
B11: Cost per home — Southern ($000) | C11: ='Segment Build'!G22
B12: Land sale revenue | C12: =Assumptions!G28
B13: Financial services revenue | C13: ='Segment Build'!G29
B14: Diluted shares (000) | C14: =IS!G36
B15: Northern competition premium (pp) | C15: =Assumptions!G14
B16: Neutral mortgage rate (%) | C16: =Assumptions!$C$9
B17: Northern base incentive / rate slope | C17: =Assumptions!$C$12
B18: Northern rate slope | C18: =Assumptions!$C$13
B19: Southern base incentive | C19: =Assumptions!$C$15
B20: Southern rate slope | C20: =Assumptions!$C$16
B21: Selling (% of homebuilding revenue) | C21: =Assumptions!G30
B22: Homebuilding G&A (% of homebuilding revenue) | C22: =Assumptions!G31
B23: Financial services pre-tax margin (%) | C23: =Assumptions!$C$37
B24: Corporate / unallocated | C24: =Assumptions!G32
B25: Inventory impairment | C25: =Assumptions!G33
B26: Net interest income | C26: =Assumptions!G34
B27: Tax rate (%) | C27: =Assumptions!$C$38
B28: Land gross margin (%) | C28: =Assumptions!$C$35
B29: Southern share of land revenue (%) | C29: =Assumptions!$C$36
B31: 2027E DILUTED EPS ($) — mortgage rate (down) x Southern competition premium (across)
B32: 30-yr mortgage rate \ competition premium (pp of gross ASP) | C32: 0.5 | D32: 1.7 | E32: 2.97 | F32: 4.2 | G32: 5.5
